Workbook
Name UPDATE: 'Data Sheet'!$E$1

Sheet Cover
E4: Equity Research Report
E9: ='Assumptions&Scenario'!K10
B10: https://sudhirkulaye.com | E10: ='Assumptions&Scenario'!U10
I15: Author:
I16: Sudhir Kulaye, CFA

Sheet Assumptions&Scenario
B3: =$K$10
B4: Standalone Assumptions
C6: Standalone Assumptions | Y6: Guidance
D10: Short Name | K10: ='Data Sheet'!B1 | P10: Last Update | U10: =TODAY() | Y10: Terminal EBIT Margin | AC10: =IFERROR(HistoricalData!AH333, HistoricalData!AH375)
D11: Ticker | K11: {=_xlfn.TEXTJOIN("", TRUE, LEFT(TRIM(MID(SUBSTITUTE(K10, " ", REPT(" ", 100)), (ROW(INDIRECT("1:" & LEN(K10) - LEN(SUBSTITUTE(K10, " ", ""))) )-1)*100+1, 100)), 1))} | P11: Is Financial | U11: No | Y11: Terminal After Tax Return on Capital | AC11: =IFERROR(HistoricalData!U562, U19)
D13: Terminal Growth | P13: Discount Rate | Y13: Industry Sales to Capital | AC13: =HistoricalData!U559
D14: Second Stage Period | K14: 10 | P14: Debt Portion | U14: =HistoricalData!U645 | Y14: Debt Portion | AC14: =HistoricalData!U645
D15: Second Stage Growth Rate | K15: 0.1 | P15: Equity Portion | U15: =1-U14 | Y15: Risk Free Rate | AC15: 0.065 | AD15: (10-Year G-Sec yield)
D16: Terminal Growth Beyond Second Stage | K16: 0.05 | P16: Cost of Debt | U16: =AC17 | Y16: Bond Ratings | AC16: AAA
D17: Adjusted Terminal Growth Rate | K17: =K16+(K15-K16)*(K14/40) | P17: Tax Rate | U17: 0.25 | Y17: Cost of Debt | AC17: =AC15 + CHOOSE(MATCH(AC16, {"AAA","AA","A","BBB","BB or Lower"}, 0), 2%, 3%, 4.5%, 6%, 8%) | AD17: (Inhouse Calculation)
D18: Terminal EBIT Margin | K18: =IFERROR(HistoricalData!AH333, HistoricalData!AH375) | P18: Cost of Equity | U18: =AC21 | Y18: NIFTY 10 Yr Return | AC18: 0.123
D19: Terminal After Tax Return on Capital | K19: =IFERROR(HistoricalData!U562, U19) | P19: WACC% | U19: =U14*U16*(1-U17)+U15*U18 | Y19: ERP | AC19: =AC18-AC15
D20: Terminal After Tax Return on Equity | K20: =IFERROR(HistoricalData!U564, U20) | P20: Fwd. Market Multiple (x) | U20: 19.5 | Y20: Beta | AC20: 1 | AD20: Update Beta
D21: Terminal Reinvestment Rate | K21: =K17/K19 | P21: Premium / Discount to Market Multiple | U21: =AC23 | Y21: Cost of Equity | AC21: =AC15+AC20*AC19
D22: Industry Sales to Capital | K22: =HistoricalData!U559 | P22: Other Adjustment for ESOP & Contingent Liability | U22: 0 | Y22: Stock Type | AC22: Quality compounder
Y23: Premium / Discount to Market Multiple | AC23: =CHOOSE(MATCH(AC22, {"High-growth","Quality compounder","Market average","Slow-growth","Troubled/distressed"}, 0), 50%, 30%, 0%, -25%, -50%)
D24: Variable Cost Per Unit | P24: Fixed Cost
K25: =L88 | L25: Inflation Y1 | M25: Inflation Y2 | S25: =L88 | T25: Inflation Y1 | U25: Inflation Y2
D26: Raw Material | I26: ( ₹ ) | K26: =HistoricalData!U199*(1+L26) | L26: =IFERROR(HistoricalData!Y199/HistoricalData!U199-1, 0) | M26: =IFERROR(HistoricalData!Z199/HistoricalData!Y199-1, 0) | P26: Employee Cost | R26: (₹ crore) | S26: =HistoricalData!U189*(1+T26) | T26: =IFERROR(HistoricalData!Y189/HistoricalData!U189-1, 0) | U26: =IFERROR(HistoricalData!Z189/HistoricalData!Y189-1, 0)
D27: Power and Fuel | I27: ( ₹ ) | K27: =HistoricalData!U200*(1+L27) | L27: =IFERROR(HistoricalData!Y200/HistoricalData!U200-1, 0) | M27: =IFERROR(HistoricalData!Z200/HistoricalData!Y200-1, 0) | P27: Fixed Cost Iteam 2 | R27: (₹ crore) | S27: =HistoricalData!U190*(1+T27) | T27: =IFERROR(HistoricalData!Y190/HistoricalData!U190-1, 0) | U27: =IFERROR(HistoricalData!Z190/HistoricalData!Y190-1, 0)
D28: Other Mfr. Exp | I28: ( ₹ ) | K28: =HistoricalData!U201*(1+L28) | L28: =IFERROR(HistoricalData!Y201/HistoricalData!U201-1, 0) | M28: =IFERROR(HistoricalData!Z201/HistoricalData!Y201-1, 0) | P28: Fixed Cost Iteam 3 | R28: (₹ crore) | S28: =HistoricalData!U191*(1+T28) | T28: =IFERROR(HistoricalData!Y191/HistoricalData!U191-1, 0) | U28: =IFERROR(HistoricalData!Z191/HistoricalData!Y191-1, 0)
D29: Variable Cost Iteam 4 | I29: ( ₹ ) | K29: =HistoricalData!U202*(1+L29) | L29: =IFERROR(HistoricalData!Y202/HistoricalData!U202-1, 0) | M29: =IFERROR(HistoricalData!Z202/HistoricalData!Y202-1, 0) | P29: Selling and Admin | R29: (₹ crore) | S29: =HistoricalData!U192*(1+T29) | T29: =IFERROR(HistoricalData!Y192/HistoricalData!U192-1, 0) | U29: =IFERROR(HistoricalData!Z192/HistoricalData!Y192-1, 0)
D30: Other Variable Cost | I30: ( ₹ ) | K30: =HistoricalData!U203*(1+L30) | L30: =IFERROR(HistoricalData!Y203/HistoricalData!U203-1, 0) | M30: =IFERROR(HistoricalData!Z203/HistoricalData!Y203-1, 0) | P30: Other Fixed Cost | R30: (₹ crore) | S30: =HistoricalData!U193*(1+T30) | T30: =IFERROR(HistoricalData!Y193/HistoricalData!U193-1, 0) | U30: =IFERROR(HistoricalData!Z193/HistoricalData!Y193-1, 0)
D31: Total Variable Cost | I31: ( ₹ ) | K31: =HistoricalData!U204*(1+L31) | L31: =IFERROR(HistoricalData!Y204/HistoricalData!U204-1, 0) | M31: =IFERROR(HistoricalData!Z204/HistoricalData!Y204-1, 0) | P31: Total Fixed Cost | R31: (₹ crore) | S31: =HistoricalData!U194*(1+T31) | T31: =IFERROR(HistoricalData!Y194/HistoricalData!U194-1, 0) | U31: =IFERROR(HistoricalData!Z194/HistoricalData!Y194-1, 0)
D34: Interest Rates | P34: Depreciation | Y34: Interest Rates Guidance
D35: Interest earned on Investments: | K35: =IFERROR(HistoricalData!U629, 7%) | P35: Depreciation Method | U35: Stright Line | Y35: Interest earned on Investments: | AC35: =IFERROR(HistoricalData!U629, 7%)
D36: Interest rate on Bank Revolver: | K36: =IFERROR(HistoricalData!$U$639, 9.5%) | P36: Years remaining for depreciation of existing assets: | U36: =HistoricalData!$U$560 | Y36: Interest rate on Bank Revolver: | AC36: =IFERROR(HistoricalData!$U$639, 9.5%)
D37: Interest rate on Senior Secured Term Debt: | K37: =IFERROR(HistoricalData!$U$639, 9.5%) | P37: Years used for depreciation of new assets: | U37: =HistoricalData!$U$560 | Y37: Interest rate on Senior Secured Term Debt: | AC37: =IFERROR(HistoricalData!$U$639, 9.5%)
D40: Capacity | K40: =L88 | P40: Equity
D41: Capacity | K41: =HistoricalData!AH37 | P41: Stock Price | U41: =HistoricalData!U394
D42: Unit of Capacity | K42: (Units) | P42: No. of outstanding shares in Crores | U42: =HistoricalData!U391
D43: Capacity Multiplier For Revenue in Cr. | K43: 1 | P43: Common Dividend Payout Rate | U43: =IFERROR(AVERAGE(HistoricalData!T653:U653), 0)
D44: Capacity Per Unit | K44: (₹/Unit) | P44: Materiality Threshold | U44: 0.05
P45: Requied CAR Ratio | U45: 0.12
B49: =$K$10
B50: Annual Inputs and Assumptions
L51: Projected
C52: FIN Years | K52: ="FY"&TEXT(DATE(YEAR('Data Sheet'!K16)+(MONTH('Data Sheet'!K16)>3),1,1),"YY") | L52: ="FY"&TEXT(RIGHT(K52,2)+COLUMN()-COLUMN(K52),"00") | M52: ="FY"&TEXT(RIGHT(L52,2)+COLUMN()-COLUMN(L52),"00") | N52: ="FY"&TEXT(RIGHT(M52,2)+COLUMN()-COLUMN(M52),"00") | O52: ="FY"&TEXT(RIGHT(N52,2)+COLUMN()-COLUMN(N52),"00") | P52: ="FY"&TEXT(RIGHT(O52,2)+COLUMN()-COLUMN(O52),"00") | Q52: ="FY"&TEXT(RIGHT(P52,2)+COLUMN()-COLUMN(P52),"00") | R52: ="FY"&TEXT(RIGHT(Q52,2)+COLUMN()-COLUMN(Q52),"00") | S52: ="FY"&TEXT(RIGHT(R52,2)+COLUMN()-COLUMN(R52),"00") | ... U52: ="FY"&TEXT(RIGHT(T52,2)+COLUMN()-COLUMN(T52),"00")
C56: Income Statement
D57: Exceptional item | H57: (₹ crore) | L57: 0 | M57: 0 | N57: 0 | O57: 0 | P57: 0 | Q57: 0 | R57: 0 | S57: 0 | T57: 0 | U57: 0
...

Sheet HistoricalData
B3: ='Assumptions&Scenario'!$K$10
B4: Annual Revenue History | Y4: Annual Revenue Forecast
C6: FIN Years | J6: ="FY"&TEXT(RIGHT(K6,2)-(COLUMN(K6)-COLUMN()),"00") | K6: ="FY"&TEXT(RIGHT(L6,2)-(COLUMN(L6)-COLUMN()),"00") | L6: ="FY"&TEXT(RIGHT(M6,2)-(COLUMN(M6)-COLUMN()),"00") | M6: ="FY"&TEXT(RIGHT(N6,2)-(COLUMN(N6)-COLUMN()),"00") | N6: ="FY"&TEXT(RIGHT(O6,2)-(COLUMN(O6)-COLUMN()),"00") | O6: ="FY"&TEXT(RIGHT(P6,2)-(COLUMN(P6)-COLUMN()),"00") | P6: ="FY"&TEXT(RIGHT(Q6,2)-(COLUMN(Q6)-COLUMN()),"00") | Q6: ="FY"&TEXT(RIGHT(R6,2)-(COLUMN(R6)-COLUMN()),"00") | ... T6: ="FY"&TEXT(RIGHT(U6,2)-(COLUMN(U6)-COLUMN()),"00") | U6: ="FY"&TEXT(DATE(YEAR('Data Sheet'!$K$16)+(MONTH('Data Sheet'!$K$16)>3),1,1),"YY") | Y6: =Model!$L$6 | Z6: ="FY"&TEXT(RIGHT(Y6,2)+COLUMN()-COLUMN(Y6),"00") | AA6: ="FY"&TEXT(RIGHT(Z6,2)+COLUMN()-COLUMN(Z6),"00") | AB6: ="FY"&TEXT(RIGHT(AA6,2)+COLUMN()-COLUMN(AA6),"00") | AC6: ="FY"&TEXT(RIGHT(AB6,2)+COLUMN()-COLUMN(AB6),"00") | AD6: ="FY"&TEXT(RIGHT(AC6,2)+COLUMN()-COLUMN(AC6),"00") | AE6: ="FY"&TEXT(RIGHT(AD6,2)+COLUMN()-COLUMN(AD6),"00") | AF6: ="FY"&TEXT(RIGHT(AE6,2)+COLUMN()-COLUMN(AE6),"00") | AG6: ="FY"&TEXT(RIGHT(AF6,2)+COLUMN()-COLUMN(AF6),"00") | AH6: ="FY"&TEXT(RIGHT(AG6,2)+COLUMN()-COLUMN(AG6),"00")
C10: Revenue | H10: (₹ crore) | L10: =IFERROR('Data Sheet'!B17, 0) | M10: =IFERROR('Data Sheet'!C17, 0) | N10: =IFERROR('Data Sheet'!D17, 0) | O10: =IFERROR('Data Sheet'!E17, 0) | P10: =IFERROR('Data Sheet'!F17, 0) | Q10: =IFERROR('Data Sheet'!G17, 0) | R10: =IFERROR('Data Sheet'!H17, 0) | S10: =IFERROR('Data Sheet'!I17, 0) | ... U10: =IFERROR('Data Sheet'!K17, 0) | Y10: {=IFERROR(_xlfn.FORECAST.LINEAR(RIGHT(Y$6,2), $J10:$U10, VALUE(RIGHT($J$6:$U$6,2))), 0)} | Z10: {=IFERROR(_xlfn.FORECAST.LINEAR(RIGHT(Z$6,2), $J10:$U10, VALUE(RIGHT($J$6:$U$6,2))), 0)} | AA10: {=IFERROR(_xlfn.FORECAST.LINEAR(RIGHT(AA$6,2), $J10:$U10, VALUE(RIGHT($J$6:$U$6,2))), 0)} | AB10: {=IFERROR(_xlfn.FORECAST.LINEAR(RIGHT(AB$6,2), $J10:$U10, VALUE(RIGHT($J$6:$U$6,2))), 0)} | AC10: {=IFERROR(_xlfn.FORECAST.LINEAR(RIGHT(AC$6,2), $J10:$U10, VALUE(RIGHT($J$6:$U$6,2))), 0)} | AD10: {=IFERROR(_xlfn.FORECAST.LINEAR(RIGHT(AD$6,2), $J10:$U10, VALUE(RIGHT($J$6:$U$6,2))), 0)} | AE10: {=IFERROR(_xlfn.FORECAST.LINEAR(RIGHT(AE$6,2), $J10:$U10, VALUE(RIGHT($J$6:$U$6,2))), 0)} | AF10: {=IFERROR(_xlfn.FORECAST.LINEAR(RIGHT(AF$6,2), $J10:$U10, VALUE(RIGHT($J$6:$U$6,2))), 0)} | ... AH10: {=IFERROR(_xlfn.FORECAST.LINEAR(RIGHT(AH$6,2), $J10:$U10, VALUE(RIGHT($J$6:$U$6,2))), 0)}
D11: Revenue Growth | K11: =IFERROR(K10/J10-1, 0) | L11: =IFERROR(L10/K10-1, 0) | M11: =IFERROR(M10/L10-1, 0) | N11: =IFERROR(N10/M10-1, 0) | O11: =IFERROR(O10/N10-1, 0) | P11: =IFERROR(P10/O10-1, 0) | Q11: =IFERROR(Q10/P10-1, 0) | R11: =IFERROR(R10/Q10-1, 0) | ... U11: =IFERROR(U10/T10-1, 0) | Y11: =IFERROR(Y10/U10-1, 0) | Z11: =IFERROR(Z10/Y10-1, 0) | AA11: =IFERROR(AA10/Z10-1, 0) | AB11: =IFERROR(AB10/AA10-1, 0) | AC11: =IFERROR(AC10/AB10-1, 0) | AD11: =IFERROR(AD10/AC10-1, 0) | AE11: =IFERROR(AE10/AD10-1, 0) | AF11: =IFERROR(AF10/AE10-1, 0) | AG11: =IFERROR(AG10/AF10-1, 0) | AH11: =IFERROR(AH10/AG10-1, 0)
C13: Segmental Revenue | H13: (₹ crore)
D14: Segment1 | Y14: {=IFERROR(_xlfn.FORECAST.LINEAR(RIGHT(Y$6,2), $J14:$U14, VALUE(RIGHT($J$6:$U$6,2))), 0)} | Z14: {=IFERROR(_xlfn.FORECAST.LINEAR(RIGHT(Z$6,2), $J14:$U14, VALUE(RIGHT($J$6:$U$6,2))), 0)} | AA14: {=IFERROR(_xlfn.FORECAST.LINEAR(RIGHT(AA$6,2), $J14:$U14, VALUE(RIGHT($J$6:$U$6,2))), 0)} | AB14: {=IFERROR(_xlfn.FORECAST.LINEAR(RIGHT(AB$6,2), $J14:$U14, VALUE(RIGHT($J$6:$U$6,2))), 0)} | AC14: {=IFERROR(_xlfn.FORECAST.LINEAR(RIGHT(AC$6,2), $J14:$U14, VALUE(RIGHT($J$6:$U$6,2))), 0)} | AD14: {=IFERROR(_xlfn.FORECAST.LINEAR(RIGHT(AD$6,2), $J14:$U14, VALUE(RIGHT($J$6:$U$6,2))), 0)} | AE14: {=IFERROR(_xlfn.FORECAST.LINEAR(RIGHT(AE$6,2), $J14:$U14, VALUE(RIGHT($J$6:$U$6,2))), 0)} | AF14: {=IFERROR(_xlfn.FORECAST.LINEAR(RIGHT(AF$6,2), $J14:$U14, VALUE(RIGHT($J$6:$U$6,2))), 0)} | ... AH14: {=IFERROR(_xlfn.FORECAST.LINEAR(RIGHT(AH$6,2), $J14:$U14, VALUE(RIGHT($J$6:$U$6,2))), 0)}
D15: Segment2 | Y15: {=IFERROR(_xlfn.FORECAST.LINEAR(RIGHT(Y$6,2), $J15:$U15, VALUE(RIGHT($J$6:$U$6,2))), 0)} | Z15: {=IFERROR(_xlfn.FORECAST.LINEAR(RIGHT(Z$6,2), $J15:$U15, VALUE(RIGHT($J$6:$U$6,2))), 0)} | AA15: {=IFERROR(_xlfn.FORECAST.LINEAR(RIGHT(AA$6,2), $J15:$U15, VALUE(RIGHT($J$6:$U$6,2))), 0)} | AB15: {=IFERROR(_xlfn.FORECAST.LINEAR(RIGHT(AB$6,2), $J15:$U15, VALUE(RIGHT($J$6:$U$6,2))), 0)} | AC15: {=IFERROR(_xlfn.FORECAST.LINEAR(RIGHT(AC$6,2), $J15:$U15, VALUE(RIGHT($J$6:$U$6,2))), 0)} | AD15: {=IFERROR(_xlfn.FORECAST.LINEAR(RIGHT(AD$6,2), $J15:$U15, VALUE(RIGHT($J$6:$U$6,2))), 0)} | AE15: {=IFERROR(_xlfn.FORECAST.LINEAR(RIGHT(AE$6,2), $J15:$U15, VALUE(RIGHT($J$6:$U$6,2))), 0)} | AF15: {=IFERROR(_xlfn.FORECAST.LINEAR(RIGHT(AF$6,2), $J15:$U15, VALUE(RIGHT($J$6:$U$6,2))), 0)} | ... AH15: {=IFERROR(_xlfn.FORECAST.LINEAR(RIGHT(AH$6,2), $J15:$U15, VALUE(RIGHT($J$6:$U$6,2))), 0)}
D16: Segment3 | Y16: {=IFERROR(_xlfn.FORECAST.LINEAR(RIGHT(Y$6,2), $J16:$U16, VALUE(RIGHT($J$6:$U$6,2))), 0)} | Z16: {=IFERROR(_xlfn.FORECAST.LINEAR(RIGHT(Z$6,2), $J16:$U16, VALUE(RIGHT($J$6:$U$6,2))), 0)} | AA16: {=IFERROR(_xlfn.FORECAST.LINEAR(RIGHT(AA$6,2), $J16:$U16, VALUE(RIGHT($J$6:$U$6,2))), 0)} | AB16: {=IFERROR(_xlfn.FORECAST.LINEAR(RIGHT(AB$6,2), $J16:$U16, VALUE(RIGHT($J$6:$U$6,2))), 0)} | AC16: {=IFERROR(_xlfn.FORECAST.LINEAR(RIGHT(AC$6,2), $J16:$U16, VALUE(RIGHT($J$6:$U$6,2))), 0)} | AD16: {=IFERROR(_xlfn.FORECAST.LINEAR(RIGHT(AD$6,2), $J16:$U16, VALUE(RIGHT($J$6:$U$6,2))), 0)} | AE16: {=IFERROR(_xlfn.FORECAST.LINEAR(RIGHT(AE$6,2), $J16:$U16, VALUE(RIGHT($J$6:$U$6,2))), 0)} | AF16: {=IFERROR(_xlfn.FORECAST.LINEAR(RIGHT(AF$6,2), $J16:$U16, VALUE(RIGHT($J$6:$U$6,2))), 0)} | ... AH16: {=IFERROR(_xlfn.FORECAST.LINEAR(RIGHT(AH$6,2), $J16:$U16, VALUE(RIGHT($J$6:$U$6,2))), 0)}
D17: Segment4 | Y17: {=IFERROR(_xlfn.FORECAST.LINEAR(RIGHT(Y$6,2), $J17:$U17, VALUE(RIGHT($J$6:$U$6,2))), 0)} | Z17: {=IFERROR(_xlfn.FORECAST.LINEAR(RIGHT(Z$6,2), $J17:$U17, VALUE(RIGHT($J$6:$U$6,2))), 0)} | AA17: {=IFERROR(_xlfn.FORECAST.LINEAR(RIGHT(AA$6,2), $J17:$U17, VALUE(RIGHT($J$6:$U$6,2))), 0)} | AB17: {=IFERROR(_xlfn.FORECAST.LINEAR(RIGHT(AB$6,2), $J17:$U17, VALUE(RIGHT($J$6:$U$6,2))), 0)} | AC17: {=IFERROR(_xlfn.FORECAST.LINEAR(RIGHT(AC$6,2), $J17:$U17, VALUE(RIGHT($J$6:$U$6,2))), 0)} | AD17: {=IFERROR(_xlfn.FORECAST.LINEAR(RIGHT(AD$6,2), $J17:$U17, VALUE(RIGHT($J$6:$U$6,2))), 0)} | AE17: {=IFERROR(_xlfn.FORECAST.LINEAR(RIGHT(AE$6,2), $J17:$U17, VALUE(RIGHT($J$6:$U$6,2))), 0)} | AF17: {=IFERROR(_xlfn.FORECAST.LINEAR(RIGHT(AF$6,2), $J17:$U17, VALUE(RIGHT($J$6:$U$6,2))), 0)} | ... AH17: {=IFERROR(_xlfn.FORECAST.LINEAR(RIGHT(AH$6,2), $J17:$U17, VALUE(RIGHT($J$6:$U$6,2))), 0)}
D18: Segment5 | Y18: {=IFERROR(_xlfn.FORECAST.LINEAR(RIGHT(Y$6,2), $J18:$U18, VALUE(RIGHT($J$6:$U$6,2))), 0)} | Z18: {=IFERROR(_xlfn.FORECAST.LINEAR(RIGHT(Z$6,2), $J18:$U18, VALUE(RIGHT($J$6:$U$6,2))), 0)} | AA18: {=IFERROR(_xlfn.FORECAST.LINEAR(RIGHT(AA$6,2), $J18:$U18, VALUE(RIGHT($J$6:$U$6,2))), 0)} | AB18: {=IFERROR(_xlfn.FORECAST.LINEAR(RIGHT(AB$6,2), $J18:$U18, VALUE(RIGHT($J$6:$U$6,2))), 0)} | AC18: {=IFERROR(_xlfn.FORECAST.LINEAR(RIGHT(AC$6,2), $J18:$U18, VALUE(RIGHT($J$6:$U$6,2))), 0)} | AD18: {=IFERROR(_xlfn.FORECAST.LINEAR(RIGHT(AD$6,2), $J18:$U18, VALUE(RIGHT($J$6:$U$6,2))), 0)} | AE18: {=IFERROR(_xlfn.FORECAST.LINEAR(RIGHT(AE$6,2), $J18:$U18, VALUE(RIGHT($J$6:$U$6,2))), 0)} | AF18: {=IFERROR(_xlfn.FORECAST.LINEAR(RIGHT(AF$6,2), $J18:$U18, VALUE(RIGHT($J$6:$U$6,2))), 0)} | ... AH18: {=IFERROR(_xlfn.FORECAST.LINEAR(RIGHT(AH$6,2), $J18:$U18, VALUE(RIGHT($J$6:$U$6,2))), 0)}
D19: Segment6 | Y19: {=IFERROR(_xlfn.FORECAST.LINEAR(RIGHT(Y$6,2), $J19:$U19, VALUE(RIGHT($J$6:$U$6,2))), 0)} | Z19: {=IFERROR(_xlfn.FORECAST.LINEAR(RIGHT(Z$6,2), $J19:$U19, VALUE(RIGHT($J$6:$U$6,2))), 0)} | AA19: {=IFERROR(_xlfn.FORECAST.LINEAR(RIGHT(AA$6,2), $J19:$U19, VALUE(RIGHT($J$6:$U$6,2))), 0)} | AB19: {=IFERROR(_xlfn.FORECAST.LINEAR(RIGHT(AB$6,2), $J19:$U19, VALUE(RIGHT($J$6:$U$6,2))), 0)} | AC19: {=IFERROR(_xlfn.FORECAST.LINEAR(RIGHT(AC$6,2), $J19:$U19, VALUE(RIGHT($J$6:$U$6,2))), 0)} | AD19: {=IFERROR(_xlfn.FORECAST.LINEAR(RIGHT(AD$6,2), $J19:$U19, VALUE(RIGHT($J$6:$U$6,2))), 0)} | AE19: {=IFERROR(_xlfn.FORECAST.LINEAR(RIGHT(AE$6,2), $J19:$U19, VALUE(RIGHT($J$6:$U$6,2))), 0)} | AF19: {=IFERROR(_xlfn.FORECAST.LINEAR(RIGHT(AF$6,2), $J19:$U19, VALUE(RIGHT($J$6:$U$6,2))), 0)} | ... AH19: {=IFERROR(_xlfn.FORECAST.LINEAR(RIGHT(AH$6,2), $J19:$U19, VALUE(RIGHT($J$6:$U$6,2))), 0)}
D20: Segment7 | Y20: {=IFERROR(_xlfn.FORECAST.LINEAR(RIGHT(Y$6,2), $J20:$U20, VALUE(RIGHT($J$6:$U$6,2))), 0)} | Z20: {=IFERROR(_xlfn.FORECAST.LINEAR(RIGHT(Z$6,2), $J20:$U20, VALUE(RIGHT($J$6:$U$6,2))), 0)} | AA20: {=IFERROR(_xlfn.FORECAST.LINEAR(RIGHT(AA$6,2), $J20:$U20, VALUE(RIGHT($J$6:$U$6,2))), 0)} | AB20: {=IFERROR(_xlfn.FORECAST.LINEAR(RIGHT(AB$6,2), $J20:$U20, VALUE(RIGHT($J$6:$U$6,2))), 0)} | AC20: {=IFERROR(_xlfn.FORECAST.LINEAR(RIGHT(AC$6,2), $J20:$U20, VALUE(RIGHT($J$6:$U$6,2))), 0)} | AD20: {=IFERROR(_xlfn.FORECAST.LINEAR(RIGHT(AD$6,2), $J20:$U20, VALUE(RIGHT($J$6:$U$6,2))), 0)} | AE20: {=IFERROR(_xlfn.FORECAST.LINEAR(RIGHT(AE$6,2), $J20:$U20, VALUE(RIGHT($J$6:$U$6,2))), 0)} | AF20: {=IFERROR(_xlfn.FORECAST.LINEAR(RIGHT(AF$6,2), $J20:$U20, VALUE(RIGHT($J$6:$U$6,2))), 0)} | ... AH20: {=IFERROR(_xlfn.FORECAST.LINEAR(RIGHT(AH$6,2), $J20:$U20, VALUE(RIGHT($J$6:$U$6,2))), 0)}
D21: Segment8 | Y21: {=IFERROR(_xlfn.FORECAST.LINEAR(RIGHT(Y$6,2), $J21:$U21, VALUE(RIGHT($J$6:$U$6,2))), 0)} | Z21: {=IFERROR(_xlfn.FORECAST.LINEAR(RIGHT(Z$6,2), $J21:$U21, VALUE(RIGHT($J$6:$U$6,2))), 0)} | AA21: {=IFERROR(_xlfn.FORECAST.LINEAR(RIGHT(AA$6,2), $J21:$U21, VALUE(RIGHT($J$6:$U$6,2))), 0)} | AB21: {=IFERROR(_xlfn.FORECAST.LINEAR(RIGHT(AB$6,2), $J21:$U21, VALUE(RIGHT($J$6:$U$6,2))), 0)} | AC21: {=IFERROR(_xlfn.FORECAST.LINEAR(RIGHT(AC$6,2), $J21:$U21, VALUE(RIGHT($J$6:$U$6,2))), 0)} | AD21: {=IFERROR(_xlfn.FORECAST.LINEAR(RIGHT(AD$6,2), $J21:$U21, VALUE(RIGHT($J$6:$U$6,2))), 0)} | AE21: {=IFERROR(_xlfn.FORECAST.LINEAR(RIGHT(AE$6,2), $J21:$U21, VALUE(RIGHT($J$6:$U$6,2))), 0)} | AF21: {=IFERROR(_xlfn.FORECAST.LINEAR(RIGHT(AF$6,2), $J21:$U21, VALUE(RIGHT($J$6:$U$6,2))), 0)} | ... AH21: {=IFERROR(_xlfn.FORECAST.LINEAR(RIGHT(AH$6,2), $J21:$U21, VALUE(RIGHT($J$6:$U$6,2))), 0)}
D22: Segment9 | Y22: {=IFERROR(_xlfn.FORECAST.LINEAR(RIGHT(Y$6,2), $J22:$U22, VALUE(RIGHT($J$6:$U$6,2))), 0)} | Z22: {=IFERROR(_xlfn.FORECAST.LINEAR(RIGHT(Z$6,2), $J22:$U22, VALUE(RIGHT($J$6:$U$6,2))), 0)} | AA22: {=IFERROR(_xlfn.FORECAST.LINEAR(RIGHT(AA$6,2), $J22:$U22, VALUE(RIGHT($J$6:$U$6,2))), 0)} | AB22: {=IFERROR(_xlfn.FORECAST.LINEAR(RIGHT(AB$6,2), $J22:$U22, VALUE(RIGHT($J$6:$U$6,2))), 0)} | AC22: {=IFERROR(_xlfn.FORECAST.LINEAR(RIGHT(AC$6,2), $J22:$U22, VALUE(RIGHT($J$6:$U$6,2))), 0)} | AD22: {=IFERROR(_xlfn.FORECAST.LINEAR(RIGHT(AD$6,2), $J22:$U22, VALUE(RIGHT($J$6:$U$6,2))), 0)} | AE22: {=IFERROR(_xlfn.FORECAST.LINEAR(RIGHT(AE$6,2), $J22:$U22, VALUE(RIGHT($J$6:$U$6,2))), 0)} | AF22: {=IFERROR(_xlfn.FORECAST.LINEAR(RIGHT(AF$6,2), $J22:$U22, VALUE(RIGHT($J$6:$U$6,2))), 0)} | ... AH22: {=IFERROR(_xlfn.FORECAST.LINEAR(RIGHT(AH$6,2), $J22:$U22, VALUE(RIGHT($J$6:$U$6,2))), 0)}
D23: Segment10 | Y23: {=IFERROR(_xlfn.FORECAST.LINEAR(RIGHT(Y$6,2), $J23:$U23, VALUE(RIGHT($J$6:$U$6,2))), 0)} | Z23: {=IFERROR(_xlfn.FORECAST.LINEAR(RIGHT(Z$6,2), $J23:$U23, VALUE(RIGHT($J$6:$U$6,2))), 0)} | AA23: {=IFERROR(_xlfn.FORECAST.LINEAR(RIGHT(AA$6,2), $J23:$U23, VALUE(RIGHT($J$6:$U$6,2))), 0)} | AB23: {=IFERROR(_xlfn.FORECAST.LINEAR(RIGHT(AB$6,2), $J23:$U23, VALUE(RIGHT($J$6:$U$6,2))), 0)} | AC23: {=IFERROR(_xlfn.FORECAST.LINEAR(RIGHT(AC$6,2), $J23:$U23, VALUE(RIGHT($J$6:$U$6,2))), 0)} | AD23: {=IFERROR(_xlfn.FORECAST.LINEAR(RIGHT(AD$6,2), $J23:$U23, VALUE(RIGHT($J$6:$U$6,2))), 0)} | AE23: {=IFERROR(_xlfn.FORECAST.LINEAR(RIGHT(AE$6,2), $J23:$U23, VALUE(RIGHT($J$6:$U$6,2))), 0)} | AF23: {=IFERROR(_xlfn.FORECAST.LINEAR(RIGHT(AF$6,2), $J23:$U23, VALUE(RIGHT($J$6:$U$6,2))), 0)} | ... AH23: {=IFERROR(_xlfn.FORECAST.LINEAR(RIGHT(AH$6,2), $J23:$U23, VALUE(RIGHT($J$6:$U$6,2))), 0)}
D24: Segmental Revenue | J24: =SUM(J14:J23) | K24: =SUM(K14:K23) | L24: =SUM(L14:L23) | M24: =SUM(M14:M23) | N24: =SUM(N14:N23) | O24: =SUM(O14:O23) | P24: =SUM(P14:P23) | Q24: =SUM(Q14:Q23) | ... U24: =SUM(U14:U23) | Y24: =SUM(Y14:Y23) | Z24: =SUM(Z14:Z23) | AA24: =SUM(AA14:AA23) | AB24: =SUM(AB14:AB23) | AC24: =SUM(AC14:AC23) | AD24: =SUM(AD14:AD23) | AE24: =SUM(AE14:AE23) | AF24: =SUM(AF14:AF23) | ... AH24: =SUM(AH14:AH23)
C26: Geography Revenue | H26: (₹ crore)
D27: Geography1 | Y27: {=IFERROR(_xlfn.FORECAST.LINEAR(RIGHT(Y$6,2), $J27:$U27, VALUE(RIGHT($J$6:$U$6,2))), 0)} | Z27: {=IFERROR(_xlfn.FORECAST.LINEAR(RIGHT(Z$6,2), $J27:$U27, VALUE(RIGHT($J$6:$U$6,2))), 0)} | AA27: {=IFERROR(_xlfn.FORECAST.LINEAR(RIGHT(AA$6,2), $J27:$U27, VALUE(RIGHT($J$6:$U$6,2))), 0)} | AB27: {=IFERROR(_xlfn.FORECAST.LINEAR(RIGHT(AB$6,2), $J27:$U27, VALUE(RIGHT($J$6:$U$6,2))), 0)} | AC27: {=IFERROR(_xlfn.FORECAST.LINEAR(RIGHT(AC$6,2), $J27:$U27, VALUE(RIGHT($J$6:$U$6,2))), 0)} | AD27: {=IFERROR(_xlfn.FORECAST.LINEAR(RIGHT(AD$6,2), $J27:$U27, VALUE(RIGHT($J$6:$U$6,2))), 0)} | AE27: {=IFERROR(_xlfn.FORECAST.LINEAR(RIGHT(AE$6,2), $J27:$U27, VALUE(RIGHT($J$6:$U$6,2))), 0)} | AF27: {=IFERROR(_xlfn.FORECAST.LINEAR(RIGHT(AF$6,2), $J27:$U27, VALUE(RIGHT($J$6:$U$6,2))), 0)} | ... AH27: {=IFERROR(_xlfn.FORECAST.LINEAR(RIGHT(AH$6,2), $J27:$U27, VALUE(RIGHT($J$6:$U$6,2))), 0)}
D28: Geography2 | Y28: {=IFERROR(_xlfn.FORECAST.LINEAR(RIGHT(Y$6,2), $J28:$U28, VALUE(RIGHT($J$6:$U$6,2))), 0)} | Z28: {=IFERROR(_xlfn.FORECAST.LINEAR(RIGHT(Z$6,2), $J28:$U28, VALUE(RIGHT($J$6:$U$6,2))), 0)} | AA28: {=IFERROR(_xlfn.FORECAST.LINEAR(RIGHT(AA$6,2), $J28:$U28, VALUE(RIGHT($J$6:$U$6,2))), 0)} | AB28: {=IFERROR(_xlfn.FORECAST.LINEAR(RIGHT(AB$6,2), $J28:$U28, VALUE(RIGHT($J$6:$U$6,2))), 0)} | AC28: {=IFERROR(_xlfn.FORECAST.LINEAR(RIGHT(AC$6,2), $J28:$U28, VALUE(RIGHT($J$6:$U$6,2))), 0)} | AD28: {=IFERROR(_xlfn.FORECAST.LINEAR(RIGHT(AD$6,2), $J28:$U28, VALUE(RIGHT($J$6:$U$6,2))), 0)} | AE28: {=IFERROR(_xlfn.FORECAST.LINEAR(RIGHT(AE$6,2), $J28:$U28, VALUE(RIGHT($J$6:$U$6,2))), 0)} | AF28: {=IFERROR(_xlfn.FORECAST.LINEAR(RIGHT(AF$6,2), $J28:$U28, VALUE(RIGHT($J$6:$U$6,2))), 0)} | ... AH28: {=IFERROR(_xlfn.FORECAST.LINEAR(RIGHT(AH$6,2), $J28:$U28, VALUE(RIGHT($J$6:$U$6,2))), 0)}
D29: Geography3 | Y29: {=IFERROR(_xlfn.FORECAST.LINEAR(RIGHT(Y$6,2), $J29:$U29, VALUE(RIGHT($J$6:$U$6,2))), 0)} | Z29: {=IFERROR(_xlfn.FORECAST.LINEAR(RIGHT(Z$6,2), $J29:$U29, VALUE(RIGHT($J$6:$U$6,2))), 0)} | AA29: {=IFERROR(_xlfn.FORECAST.LINEAR(RIGHT(AA$6,2), $J29:$U29, VALUE(RIGHT($J$6:$U$6,2))), 0)} | AB29: {=IFERROR(_xlfn.FORECAST.LINEAR(RIGHT(AB$6,2), $J29:$U29, VALUE(RIGHT($J$6:$U$6,2))), 0)} | AC29: {=IFERROR(_xlfn.FORECAST.LINEAR(RIGHT(AC$6,2), $J29:$U29, VALUE(RIGHT($J$6:$U$6,2))), 0)} | AD29: {=IFERROR(_xlfn.FORECAST.LINEAR(RIGHT(AD$6,2), $J29:$U29, VALUE(RIGHT($J$6:$U$6,2))), 0)} | AE29: {=IFERROR(_xlfn.FORECAST.LINEAR(RIGHT(AE$6,2), $J29:$U29, VALUE(RIGHT($J$6:$U$6,2))), 0)} | AF29: {=IFERROR(_xlfn.FORECAST.LINEAR(RIGHT(AF$6,2), $J29:$U29, VALUE(RIGHT($J$6:$U$6,2))), 0)} | ... AH29: {=IFERROR(_xlfn.FORECAST.LINEAR(RIGHT(AH$6,2), $J29:$U29, VALUE(RIGHT($J$6:$U$6,2))), 0)}
D30: Geography4 | Y30: {=IFERROR(_xlfn.FORECAST.LINEAR(RIGHT(Y$6,2), $J30:$U30, VALUE(RIGHT($J$6:$U$6,2))), 0)} | Z30: {=IFERROR(_xlfn.FORECAST.LINEAR(RIGHT(Z$6,2), $J30:$U30, VALUE(RIGHT($J$6:$U$6,2))), 0)} | AA30: {=IFERROR(_xlfn.FORECAST.LINEAR(RIGHT(AA$6,2), $J30:$U30, VALUE(RIGHT($J$6:$U$6,2))), 0)} | AB30: {=IFERROR(_xlfn.FORECAST.LINEAR(RIGHT(AB$6,2), $J30:$U30, VALUE(RIGHT($J$6:$U$6,2))), 0)} | AC30: {=IFERROR(_xlfn.FORECAST.LINEAR(RIGHT(AC$6,2), $J30:$U30, VALUE(RIGHT($J$6:$U$6,2))), 0)} | AD30: {=IFERROR(_xlfn.FORECAST.LINEAR(RIGHT(AD$6,2), $J30:$U30, VALUE(RIGHT($J$6:$U$6,2))), 0)} | AE30: {=IFERROR(_xlfn.FORECAST.LINEAR(RIGHT(AE$6,2), $J30:$U30, VALUE(RIGHT($J$6:$U$6,2))), 0)} | AF30: {=IFERROR(_xlfn.FORECAST.LINEAR(RIGHT(AF$6,2), $J30:$U30, VALUE(RIGHT($J$6:$U$6,2))), 0)} | ... AH30: {=IFERROR(_xlfn.FORECAST.LINEAR(RIGHT(AH$6,2), $J30:$U30, VALUE(RIGHT($J$6:$U$6,2))), 0)}
D31: Geography5 | Y31: {=IFERROR(_xlfn.FORECAST.LINEAR(RIGHT(Y$6,2), $J31:$U31, VALUE(RIGHT($J$6:$U$6,2))), 0)} | Z31: {=IFERROR(_xlfn.FORECAST.LINEAR(RIGHT(Z$6,2), $J31:$U31, VALUE(RIGHT($J$6:$U$6,2))), 0)} | AA31: {=IFERROR(_xlfn.FORECAST.LINEAR(RIGHT(AA$6,2), $J31:$U31, VALUE(RIGHT($J$6:$U$6,2))), 0)} | AB31: {=IFERROR(_xlfn.FORECAST.LINEAR(RIGHT(AB$6,2), $J31:$U31, VALUE(RIGHT($J$6:$U$6,2))), 0)} | AC31: {=IFERROR(_xlfn.FORECAST.LINEAR(RIGHT(AC$6,2), $J31:$U31, VALUE(RIGHT($J$6:$U$6,2))), 0)} | AD31: {=IFERROR(_xlfn.FORECAST.LINEAR(RIGHT(AD$6,2), $J31:$U31, VALUE(RIGHT($J$6:$U$6,2))), 0)} | AE31: {=IFERROR(_xlfn.FORECAST.LINEAR(RIGHT(AE$6,2), $J31:$U31, VALUE(RIGHT($J$6:$U$6,2))), 0)} | AF31: {=IFERROR(_xlfn.FORECAST.LINEAR(RIGHT(AF$6,2), $J31:$U31, VALUE(RIGHT($J$6:$U$6,2))), 0)} | ... AH31: {=IFERROR(_xlfn.FORECAST.LINEAR(RIGHT(AH$6,2), $J31:$U31, VALUE(RIGHT($J$6:$U$6,2))), 0)}
D32: Geography6 | Y32: {=IFERROR(_xlfn.FORECAST.LINEAR(RIGHT(Y$6,2), $J32:$U32, VALUE(RIGHT($J$6:$U$6,2))), 0)} | Z32: {=IFERROR(_xlfn.FORECAST.LINEAR(RIGHT(Z$6,2), $J32:$U32, VALUE(RIGHT($J$6:$U$6,2))), 0)} | AA32: {=IFERROR(_xlfn.FORECAST.LINEAR(RIGHT(AA$6,2), $J32:$U32, VALUE(RIGHT($J$6:$U$6,2))), 0)} | AB32: {=IFERROR(_xlfn.FORECAST.LINEAR(RIGHT(AB$6,2), $J32:$U32, VALUE(RIGHT($J$6:$U$6,2))), 0)} | AC32: {=IFERROR(_xlfn.FORECAST.LINEAR(RIGHT(AC$6,2), $J32:$U32, VALUE(RIGHT($J$6:$U$6,2))), 0)} | AD32: {=IFERROR(_xlfn.FORECAST.LINEAR(RIGHT(AD$6,2), $J32:$U32, VALUE(RIGHT($J$6:$U$6,2))), 0)} | AE32: {=IFERROR(_xlfn.FORECAST.LINEAR(RIGHT(AE$6,2), $J32:$U32, VALUE(RIGHT($J$6:$U$6,2))), 0)} | AF32: {=IFERROR(_xlfn.FORECAST.LINEAR(RIGHT(AF$6,2), $J32:$U32, VALUE(RIGHT($J$6:$U$6,2))), 0)} | ... AH32: {=IFERROR(_xlfn.FORECAST.LINEAR(RIGHT(AH$6,2), $J32:$U32, VALUE(RIGHT($J$6:$U$6,2))), 0)}
D33: Geography7 | Y33: {=IFERROR(_xlfn.FORECAST.LINEAR(RIGHT(Y$6,2), $J33:$U33, VALUE(RIGHT($J$6:$U$6,2))), 0)} | Z33: {=IFERROR(_xlfn.FORECAST.LINEAR(RIGHT(Z$6,2), $J33:$U33, VALUE(RIGHT($J$6:$U$6,2))), 0)} | AA33: {=IFERROR(_xlfn.FORECAST.LINEAR(RIGHT(AA$6,2), $J33:$U33, VALUE(RIGHT($J$6:$U$6,2))), 0)} | AB33: {=IFERROR(_xlfn.FORECAST.LINEAR(RIGHT(AB$6,2), $J33:$U33, VALUE(RIGHT($J$6:$U$6,2))), 0)} | AC33: {=IFERROR(_xlfn.FORECAST.LINEAR(RIGHT(AC$6,2), $J33:$U33, VALUE(RIGHT($J$6:$U$6,2))), 0)} | AD33: {=IFERROR(_xlfn.FORECAST.LINEAR(RIGHT(AD$6,2), $J33:$U33, VALUE(RIGHT($J$6:$U$6,2))), 0)} | AE33: {=IFERROR(_xlfn.FORECAST.LINEAR(RIGHT(AE$6,2), $J33:$U33, VALUE(RIGHT($J$6:$U$6,2))), 0)} | AF33: {=IFERROR(_xlfn.FORECAST.LINEAR(RIGHT(AF$6,2), $J33:$U33, VALUE(RIGHT($J$6:$U$6,2))), 0)} | ... AH33: {=IFERROR(_xlfn.FORECAST.LINEAR(RIGHT(AH$6,2), $J33:$U33, VALUE(RIGHT($J$6:$U$6,2))), 0)}
D34: Geography8 | Y34: {=IFERROR(_xlfn.FORECAST.LINEAR(RIGHT(Y$6,2), $J34:$U34, VALUE(RIGHT($J$6:$U$6,2))), 0)} | Z34: {=IFERROR(_xlfn.FORECAST.LINEAR(RIGHT(Z$6,2), $J34:$U34, VALUE(RIGHT($J$6:$U$6,2))), 0)} | AA34: {=IFERROR(_xlfn.FORECAST.LINEAR(RIGHT(AA$6,2), $J34:$U34, VALUE(RIGHT($J$6:$U$6,2))), 0)} | AB34: {=IFERROR(_xlfn.FORECAST.LINEAR(RIGHT(AB$6,2), $J34:$U34, VALUE(RIGHT($J$6:$U$6,2))), 0)} | AC34: {=IFERROR(_xlfn.FORECAST.LINEAR(RIGHT(AC$6,2), $J34:$U34, VALUE(RIGHT($J$6:$U$6,2))), 0)} | AD34: {=IFERROR(_xlfn.FORECAST.LINEAR(RIGHT(AD$6,2), $J34:$U34, VALUE(RIGHT($J$6:$U$6,2))), 0)} | AE34: {=IFERROR(_xlfn.FORECAST.LINEAR(RIGHT(AE$6,2), $J34:$U34, VALUE(RIGHT($J$6:$U$6,2))), 0)} | AF34: {=IFERROR(_xlfn.FORECAST.LINEAR(RIGHT(AF$6,2), $J34:$U34, VALUE(RIGHT($J$6:$U$6,2))), 0)} | ... AH34: {=IFERROR(_xlfn.FORECAST.LINEAR(RIGHT(AH$6,2), $J34:$U34, VALUE(RIGHT($J$6:$U$6,2))), 0)}
D35: Geography Revenue | J35: =SUM(J27:J34) | K35: =SUM(K27:K34) | L35: =SUM(L27:L34) | M35: =SUM(M27:M34) | N35: =SUM(N27:N34) | O35: =SUM(O27:O34) | P35: =SUM(P27:P34) | Q35: =SUM(Q27:Q34) | ... U35: =SUM(U27:U34) | Y35: =SUM(Y27:Y34) | Z35: =SUM(Z27:Z34) | AA35: =SUM(AA27:AA34) | AB35: =SUM(AB27:AB34) | AC35: =SUM(AC27:AC34) | AD35: =SUM(AD27:AD34) | AE35: =SUM(AE27:AE34) | AF35: =SUM(AF27:AF34) | ... AH35: =SUM(AH27:AH34)
C37: ="Total Volume "& 'Assumptions&Scenario'!K42 | H37: ='Assumptions&Scenario'!K43 | L37: =L10 | M37: =M10 | N37: =N10 | O37: =O10 | P37: =P10 | Q37: =Q10 | R37: =R10 | S37: =S10 | ... U37: =U10 | Y37: {=IFERROR(_xlfn.FORECAST.LINEAR(RIGHT(Y$6,2), $J37:$U37, VALUE(RIGHT($J$6:$U$6,2))), 0)} | Z37: {=IFERROR(_xlfn.FORECAST.LINEAR(RIGHT(Z$6,2), $J37:$U37, VALUE(RIGHT($J$6:$U$6,2))), 0)} | AA37: {=IFERROR(_xlfn.FORECAST.LINEAR(RIGHT(AA$6,2), $J37:$U37, VALUE(RIGHT($J$6:$U$6,2))), 0)} | AB37: {=IFERROR(_xlfn.FORECAST.LINEAR(RIGHT(AB$6,2), $J37:$U37, VALUE(RIGHT($J$6:$U$6,2))), 0)} | AC37: {=IFERROR(_xlfn.FORECAST.LINEAR(RIGHT(AC$6,2), $J37:$U37, VALUE(RIGHT($J$6:$U$6,2))), 0)} | AD37: {=IFERROR(_xlfn.FORECAST.LINEAR(RIGHT(AD$6,2), $J37:$U37, VALUE(RIGHT($J$6:$U$6,2))), 0)} | AE37: {=IFERROR(_xlfn.FORECAST.LINEAR(RIGHT(AE$6,2), $J37:$U37, VALUE(RIGHT($J$6:$U$6,2))), 0)} | AF37: {=IFERROR(_xlfn.FORECAST.LINEAR(RIGHT(AF$6,2), $J37:$U37, VALUE(RIGHT($J$6:$U$6,2))), 0)} | ... AH37: {=IFERROR(_xlfn.FORECAST.LINEAR(RIGHT(AH$6,2), $J37:$U37, VALUE(RIGHT($J$6:$U$6,2))), 0)}
D38: Volume Growth | K38: =IFERROR(K37/J37-1, 0) | L38: =IFERROR(L37/K37-1, 0) | M38: =IFERROR(M37/L37-1, 0) | N38: =IFERROR(N37/M37-1, 0) | O38: =IFERROR(O37/N37-1, 0) | P38: =IFERROR(P37/O37-1, 0) | Q38: =IFERROR(Q37/P37-1, 0) | R38: =IFERROR(R37/Q37-1, 0) | ... U38: =IFERROR(U37/T37-1, 0) | Y38: =IFERROR(Y37/U37-1, 0) | Z38: =IFERROR(Z37/Y37-1, 0) | AA38: =IFERROR(AA37/Z37-1, 0) | AB38: =IFERROR(AB37/AA37-1, 0) | AC38: =IFERROR(AC37/AB37-1, 0) | AD38: =IFERROR(AD37/AC37-1, 0) | AE38: =IFERROR(AE37/AD37-1, 0) | AF38: =IFERROR(AF37/AE37-1, 0) | AG38: =IFERROR(AG37/AF37-1, 0) | AH38: =IFERROR(AH37/AG37-1, 0)
C40: Revenue / Unit | H40: ='Assumptions&Scenario'!$K$44 | J40: =IFERROR(J10*$H$37/J37, 0) | K40: =IFERROR(K10*$H$37/K37, 0) | L40: =IFERROR(L10*$H$37/L37, 0) | M40: =IFERROR(M10*$H$37/M37, 0) | N40: =IFERROR(N10*$H$37/N37, 0) | O40: =IFERROR(O10*$H$37/O37, 0) | P40: =IFERROR(P10*$H$37/P37, 0) | Q40: =IFERROR(Q10*$H$37/Q37, 0) | ... U40: =IFERROR(U10*$H$37/U37, 0) | Y40: =IFERROR(Y10*$H$37/Y37, 0) | Z40: =IFERROR(Z10*$H$37/Z37, 0) | AA40: =IFERROR(AA10*$H$37/AA37, 0) | AB40: =IFERROR(AB10*$H$37/AB37, 0) | AC40: =IFERROR(AC10*$H$37/AC37, 0) | AD40: =IFERROR(AD10*$H$37/AD37, 0) | AE40: =IFERROR(AE10*$H$37/AE37, 0) | AF40: =IFERROR(AF10*$H$37/AF37, 0) | ... AH40: =IFERROR(AH10*$H$37/AH37, 0)
D41: Price Growth | K41: =IFERROR(K40/J40-1, 0) | L41: =IFERROR(L40/K40-1, 0) | M41: =IFERROR(M40/L40-1, 0) | N41: =IFERROR(N40/M40-1, 0) | O41: =IFERROR(O40/N40-1, 0) | P41: =IFERROR(P40/O40-1, 0) | Q41: =IFERROR(Q40/P40-1, 0) | R41: =IFERROR(R40/Q40-1, 0) | ... U41: =IFERROR(U40/T40-1, 0) | Y41: =IFERROR(Y40/U40-1, 0) | Z41: =IFERROR(Z40/Y40-1, 0) | AA41: =IFERROR(AA40/Z40-1, 0) | AB41: =IFERROR(AB40/AA40-1, 0) | AC41: =IFERROR(AC40/AB40-1, 0) | AD41: =IFERROR(AD40/AC40-1, 0) | AE41: =IFERROR(AE40/AD40-1, 0) | AF41: =IFERROR(AF40/AE40-1, 0) | AG41: =IFERROR(AG40/AF40-1, 0) | AH41: =IFERROR(AH40/AG40-1, 0)
B45: ='Assumptions&Scenario'!$K$10
B46: Annual Other Information History | Y46: Annual Other Information Forecast
C48: FIN Years | J48: ="FY"&TEXT(RIGHT(K48,2)-(COLUMN(K48)-COLUMN()),"00") | K48: ="FY"&TEXT(RIGHT(L48,2)-(COLUMN(L48)-COLUMN()),"00") | L48: ="FY"&TEXT(RIGHT(M48,2)-(COLUMN(M48)-COLUMN()),"00") | M48: ="FY"&TEXT(RIGHT(N48,2)-(COLUMN(N48)-COLUMN()),"00") | N48: ="FY"&TEXT(RIGHT(O48,2)-(COLUMN(O48)-COLUMN()),"00") | O48: ="FY"&TEXT(RIGHT(P48,2)-(COLUMN(P48)-COLUMN()),"00") | P48: ="FY"&TEXT(RIGHT(Q48,2)-(COLUMN(Q48)-COLUMN()),"00") | Q48: ="FY"&TEXT(RIGHT(R48,2)-(COLUMN(R48)-COLUMN()),"00") | ... T48: ="FY"&TEXT(RIGHT(U48,2)-(COLUMN(U48)-COLUMN()),"00") | U48: ="FY"&TEXT(DATE(YEAR('Data Sheet'!$K$16)+(MONTH('Data Sheet'!$K$16)>3),1,1),"YY") | Y48: =Model!$L$6 | Z48: ="FY"&TEXT(RIGHT(Y48,2)+COLUMN()-COLUMN(Y48),"00") | AA48: ="FY"&TEXT(RIGHT(Z48,2)+COLUMN()-COLUMN(Z48),"00") | AB48: ="FY"&TEXT(RIGHT(AA48,2)+COLUMN()-COLUMN(AA48),"00") | AC48: ="FY"&TEXT(RIGHT(AB48,2)+COLUMN()-COLUMN(AB48),"00") | AD48: ="FY"&TEXT(RIGHT(AC48,2)+COLUMN()-COLUMN(AC48),"00") | AE48: ="FY"&TEXT(RIGHT(AD48,2)+COLUMN()-COLUMN(AD48),"00") | AF48: ="FY"&TEXT(RIGHT(AE48,2)+COLUMN()-COLUMN(AE48),"00") | AG48: ="FY"&TEXT(RIGHT(AF48,2)+COLUMN()-COLUMN(AF48),"00") | AH48: ="FY"&TEXT(RIGHT(AG48,2)+COLUMN()-COLUMN(AG48),"00")
B87: ='Assumptions&Scenario'!$K$10
B88: Quarterly Revenue Hisotry | Y88: Quarterly Revenue Forecast
J89: 1 | K89: 2 | L89: 2 | M89: 4 | N89: 5 | O89: 6 | P89: 7 | Q89: 8 | R89: 9 | S89: 10 | T89: 11 | U89: 12 | Y89: 13 | Z89: 14 | AA89: 15 | AB89: 16 | AC89: 17 | AD89: 18 | AE89: 19 | AF89: 20 | AG89: 21 | AH89: 22
C90: Quarters | J90: ="FY"&TEXT(MID(K90,3,2)-IF(RIGHT(K90,1)="1",1,0),"00")&"Q"&CHOOSE(RIGHT(K90,1)+0,4,1,2,3) | K90: ="FY"&TEXT(MID(L90,3,2)-IF(RIGHT(L90,1)="1",1,0),"00")&"Q"&CHOOSE(RIGHT(L90,1)+0,4,1,2,3) | L90: ="FY"&TEXT(MID(M90,3,2)-IF(RIGHT(M90,1)="1",1,0),"00")&"Q"&CHOOSE(RIGHT(M90,1)+0,4,1,2,3) | M90: ="FY"&TEXT(MID(N90,3,2)-IF(RIGHT(N90,1)="1",1,0),"00")&"Q"&CHOOSE(RIGHT(N90,1)+0,4,1,2,3) | N90: ="FY"&TEXT(MID(O90,3,2)-IF(RIGHT(O90,1)="1",1,0),"00")&"Q"&CHOOSE(RIGHT(O90,1)+0,4,1,2,3) | O90: ="FY"&TEXT(MID(P90,3,2)-IF(RIGHT(P90,1)="1",1,0),"00")&"Q"&CHOOSE(RIGHT(P90,1)+0,4,1,2,3) | P90: ="FY"&TEXT(MID(Q90,3,2)-IF(RIGHT(Q90,1)="1",1,0),"00")&"Q"&CHOOSE(RIGHT(Q90,1)+0,4,1,2,3) | Q90: ="FY"&TEXT(MID(R90,3,2)-IF(RIGHT(R90,1)="1",1,0),"00")&"Q"&CHOOSE(RIGHT(R90,1)+0,4,1,2,3) | ... T90: ="FY"&TEXT(MID(U90,3,2)-IF(RIGHT(U90,1)="1",1,0),"00")&"Q"&CHOOSE(RIGHT(U90,1)+0,4,1,2,3) | U90: ="FY"&TEXT(YEAR('Data Sheet'!$K$41)+(MONTH('Data Sheet'!$K$41)>3)-2000,"00")&"Q"&INT((MOD(MONTH('Data Sheet'!$K$41)-4,12))/3)+1 | Y90: =Model!$N$31 | Z90: ="FY"&TEXT(MID(Y90,3,2)+IF(RIGHT(Y90,1)="4",1,0),"00")&"Q"&MOD(RIGHT(Y90,1),4)+1 | AA90: ="FY"&TEXT(MID(Z90,3,2)+IF(RIGHT(Z90,1)="4",1,0),"00")&"Q"&MOD(RIGHT(Z90,1),4)+1 | AB90: ="FY"&TEXT(MID(AA90,3,2)+IF(RIGHT(AA90,1)="4",1,0),"00")&"Q"&MOD(RIGHT(AA90,1),4)+1 | AC90: ="FY"&TEXT(MID(AB90,3,2)+IF(RIGHT(AB90,1)="4",1,0),"00")&"Q"&MOD(RIGHT(AB90,1),4)+1 | AD90: ="FY"&TEXT(MID(AC90,3,2)+IF(RIGHT(AC90,1)="4",1,0),"00")&"Q"&MOD(RIGHT(AC90,1),4)+1 | AE90: ="FY"&TEXT(MID(AD90,3,2)+IF(RIGHT(AD90,1)="4",1,0),"00")&"Q"&MOD(RIGHT(AD90,1),4)+1 | AF90: ="FY"&TEXT(MID(AE90,3,2)+IF(RIGHT(AE90,1)="4",1,0),"00")&"Q"&MOD(RIGHT(AE90,1),4)+1 | AG90: ="FY"&TEXT(MID(AF90,3,2)+IF(RIGHT(AF90,1)="4",1,0),"00")&"Q"&MOD(RIGHT(AF90,1),4)+1 | AH90: ="FY"&TEXT(MID(AG90,3,2)+IF(RIGHT(AG90,1)="4",1,0),"00")&"Q"&MOD(RIGHT(AG90,1),4)+1
C94: Revenue | H94: =$H$10 | L94: =IFERROR('Data Sheet'!B42, 0) | M94: =IFERROR('Data Sheet'!C42, 0) | N94: =IFERROR('Data Sheet'!D42, 0) | O94: =IFERROR('Data Sheet'!E42, 0) | P94: =IFERROR('Data Sheet'!F42, 0) | Q94: =IFERROR('Data Sheet'!G42, 0) | R94: =IFERROR('Data Sheet'!H42, 0) | S94: =IFERROR('Data Sheet'!I42, 0) | ... U94: =IFERROR('Data Sheet'!K42, 0) | Y94: =IFERROR(_xlfn.FORECAST.LINEAR(Y$89, $J94:$U94, $J$89:$U$89), 0) | Z94: =IFERROR(_xlfn.FORECAST.LINEAR(Z$89, $J94:$U94, $J$89:$U$89), 0) | AA94: =IFERROR(_xlfn.FORECAST.LINEAR(AA$89, $J94:$U94, $J$89:$U$89), 0) | AB94: =IFERROR(_xlfn.FORECAST.LINEAR(AB$89, $J94:$U94, $J$89:$U$89), 0) | AC94: =IFERROR(_xlfn.FORECAST.LINEAR(AC$89, $J94:$U94, $J$89:$U$89), 0) | AD94: =IFERROR(_xlfn.FORECAST.LINEAR(AD$89, $J94:$U94, $J$89:$U$89), 0) | AE94: =IFERROR(_xlfn.FORECAST.LINEAR(AE$89, $J94:$U94, $J$89:$U$89), 0) | AF94: =IFERROR(_xlfn.FORECAST.LINEAR(AF$89, $J94:$U94, $J$89:$U$89), 0) | ... AH94: =IFERROR(_xlfn.FORECAST.LINEAR(AH$89, $J94:$U94, $J$89:$U$89), 0)
D95: Revenue Growth | N95: =IFERROR(N94/J94-1, 0) | O95: =IFERROR(O94/K94-1, 0) | P95: =IFERROR(P94/L94-1, 0) | Q95: =IFERROR(Q94/M94-1, 0) | R95: =IFERROR(R94/N94-1, 0) | S95: =IFERROR(S94/O94-1, 0) | T95: =IFERROR(T94/P94-1, 0) | U95: =IFERROR(U94/Q94-1, 0) | Y95: =IFERROR(Y94/R94-1, 0) | Z95: =IFERROR(Z94/S94-1, 0) | AA95: =IFERROR(AA94/T94-1, 0) | AB95: =IFERROR(AB94/U94-1, 0) | AC95: =IFERROR(AC94/Y94-1, 0) | AD95: =IFERROR(AD94/Z94-1, 0) | AE95: =IFERROR(AE94/AA94-1, 0) | AF95: =IFERROR(AF94/AB94-1, 0) | AG95: =IFERROR(AG94/AC94-1, 0) | AH95: =IFERROR(AH94/AD94-1, 0)
...

Sheet Model
U2: =UPPER("Currently Running " & CHOOSE('Assumptions&Scenario'!H88, 'Assumptions&Scenario'!D102,'Assumptions&Scenario'!D103,'Assumptions&Scenario'!D104) & " Scenario")
B3: ='Assumptions&Scenario'!$K$10
B4: Annual Revenue Schedule
L5: Projected
C6: FIN Years | J6: ="FY"&TEXT(RIGHT(K6,2)-(COLUMN(K6)-COLUMN()),"00") | K6: ="FY"&TEXT(DATE(YEAR('Data Sheet'!$K$16)+(MONTH('Data Sheet'!$K$16)>3),1,1),"YY") | L6: ="FY"&TEXT(RIGHT(K6,2)+COLUMN()-COLUMN(K6),"00") | M6: ="FY"&TEXT(RIGHT(L6,2)+COLUMN()-COLUMN(L6),"00") | N6: ="FY"&TEXT(RIGHT(M6,2)+COLUMN()-COLUMN(M6),"00") | O6: ="FY"&TEXT(RIGHT(N6,2)+COLUMN()-COLUMN(N6),"00") | P6: ="FY"&TEXT(RIGHT(O6,2)+COLUMN()-COLUMN(O6),"00") | Q6: ="FY"&TEXT(RIGHT(P6,2)+COLUMN()-COLUMN(P6),"00") | R6: ="FY"&TEXT(RIGHT(Q6,2)+COLUMN()-COLUMN(Q6),"00") | S6: ="FY"&TEXT(RIGHT(R6,2)+COLUMN()-COLUMN(R6),"00") | ... U6: ="FY"&TEXT(RIGHT(T6,2)+COLUMN()-COLUMN(T6),"00")
C10: Multiplier | H10: ='Assumptions&Scenario'!K43
C11: Pricing
D12: Price Inflation | L12: ='Assumptions&Scenario'!L112 | M12: ='Assumptions&Scenario'!M112 | N12: ='Assumptions&Scenario'!N112 | O12: ='Assumptions&Scenario'!O112 | P12: ='Assumptions&Scenario'!P112 | Q12: ='Assumptions&Scenario'!Q112 | R12: ='Assumptions&Scenario'!R112 | S12: ='Assumptions&Scenario'!S112 | ... U12: ='Assumptions&Scenario'!U112
D13: Price | H13: ='Assumptions&Scenario'!K44 | J13: =HistoricalData!T40 | K13: =HistoricalData!U40 | L13: =K13*(1+L12) | M13: =L13*(1+M12) | N13: =M13*(1+N12) | O13: =N13*(1+O12) | P13: =O13*(1+P12) | Q13: =P13*(1+Q12) | R13: =Q13*(1+R12) | S13: =R13*(1+S12) | ... U13: =T13*(1+U12)
C14: Volume
D15: Capacity | L15: ='Assumptions&Scenario'!L106 | M15: ='Assumptions&Scenario'!M106 | N15: ='Assumptions&Scenario'!N106 | O15: ='Assumptions&Scenario'!O106 | P15: ='Assumptions&Scenario'!P106 | Q15: ='Assumptions&Scenario'!Q106 | R15: ='Assumptions&Scenario'!R106 | S15: ='Assumptions&Scenario'!S106 | ... U15: ='Assumptions&Scenario'!U106
D16: Volume Growth | L16: ='Assumptions&Scenario'!L118 | M16: ='Assumptions&Scenario'!M118 | N16: ='Assumptions&Scenario'!N118 | O16: ='Assumptions&Scenario'!O118 | P16: ='Assumptions&Scenario'!P118 | Q16: ='Assumptions&Scenario'!Q118 | R16: ='Assumptions&Scenario'!R118 | S16: ='Assumptions&Scenario'!S118 | ... U16: ='Assumptions&Scenario'!U118
D17: Volume | H17: ='Assumptions&Scenario'!K42 | J17: =HistoricalData!T37 | K17: =HistoricalData!U37 | L17: =K17*(1+L16) | M17: =L17*(1+M16) | N17: =M17*(1+N16) | O17: =N17*(1+O16) | P17: =O17*(1+P16) | Q17: =P17*(1+Q16) | R17: =Q17*(1+R16) | S17: =R17*(1+S16) | ... U17: =T17*(1+U16)
D18: Utilization | L18: =IFERROR(L17/L15, 0) | M18: =IFERROR(M17/M15, 0) | N18: =IFERROR(N17/N15, 0) | O18: =IFERROR(O17/O15, 0) | P18: =IFERROR(P17/P15, 0) | Q18: =IFERROR(Q17/Q15, 0) | R18: =IFERROR(R17/R15, 0) | S18: =IFERROR(S17/S15, 0) | ... U18: =IFERROR(U17/U15, 0)
C20: Revenue
D21: Revenue | H21: (₹ crore) | L21: =L13*L17/$H$10 | M21: =M13*M17/$H$10 | N21: =N13*N17/$H$10 | O21: =O13*O17/$H$10 | P21: =P13*P17/$H$10 | Q21: =Q13*Q17/$H$10 | R21: =R13*R17/$H$10 | S21: =S13*S17/$H$10 | ... U21: =U13*U17/$H$10
D22: Exchange Rate (To Cr) | H22: 1 | L22: ='Assumptions&Scenario'!L130 | M22: ='Assumptions&Scenario'!M130 | N22: ='Assumptions&Scenario'!N130 | O22: ='Assumptions&Scenario'!O130 | P22: ='Assumptions&Scenario'!P130 | Q22: ='Assumptions&Scenario'!Q130 | R22: ='Assumptions&Scenario'!R130 | S22: ='Assumptions&Scenario'!S130 | ... U22: ='Assumptions&Scenario'!U130
D23: Revenue | H23: =HistoricalData!H10 | J23: =HistoricalData!T10 | K23: =HistoricalData!U10 | L23: =L21*L22/$H22 | M23: =M21*M22/$H22 | N23: =N21*N22/$H22 | O23: =O21*O22/$H22 | P23: =P21*P22/$H22 | Q23: =Q21*Q22/$H22 | R23: =R21*R22/$H22 | S23: =S21*S22/$H22 | ... U23: =U21*U22/$H22
D24: Revenue g% | K24: =IFERROR(K23/J23-1, 0) | L24: =IFERROR(L23/K23-1, 0) | M24: =IFERROR(M23/L23-1, 0) | N24: =IFERROR(N23/M23-1, 0) | O24: =IFERROR(O23/N23-1, 0) | P24: =IFERROR(P23/O23-1, 0) | Q24: =IFERROR(Q23/P23-1, 0) | R24: =IFERROR(R23/Q23-1, 0) | ... U24: =IFERROR(U23/T23-1, 0)
U27: =$U$2
B28: ='Assumptions&Scenario'!$K$10
B29: Quarterly Revenue Schedule
L30: Projected
C31: Quarters | J31: ="FY"&TEXT(MID(K31,3,2)-IF(RIGHT(K31,1)="1",1,0),"00")&"Q"&CHOOSE(RIGHT(K31,1)+0,4,1,2,3) | K31: ="FY"&TEXT(MID(L31,3,2)-IF(RIGHT(L31,1)="1",1,0),"00")&"Q"&CHOOSE(RIGHT(L31,1)+0,4,1,2,3) | L31: ="FY"&TEXT(MID(M31,3,2)-IF(RIGHT(M31,1)="1",1,0),"00")&"Q"&CHOOSE(RIGHT(M31,1)+0,4,1,2,3) | M31: ="FY"&TEXT(YEAR('Data Sheet'!$K$41)+(MONTH('Data Sheet'!$K$41)>3)-2000,"00")&"Q"&INT((MOD(MONTH('Data Sheet'!$K$41)-4,12))/3)+1 | N31: ="FY"&TEXT(MID(M31,3,2)+IF(RIGHT(M31,1)="4",1,0),"00")&"Q"&MOD(RIGHT(M31,1),4)+1 | O31: ="FY"&TEXT(MID(N31,3,2)+IF(RIGHT(N31,1)="4",1,0),"00")&"Q"&MOD(RIGHT(N31,1),4)+1 | P31: ="FY"&TEXT(MID(O31,3,2)+IF(RIGHT(O31,1)="4",1,0),"00")&"Q"&MOD(RIGHT(O31,1),4)+1 | Q31: ="FY"&TEXT(MID(P31,3,2)+IF(RIGHT(P31,1)="4",1,0),"00")&"Q"&MOD(RIGHT(P31,1),4)+1 | R31: ="FY"&TEXT(MID(Q31,3,2)+IF(RIGHT(Q31,1)="4",1,0),"00")&"Q"&MOD(RIGHT(Q31,1),4)+1 | S31: ="FY"&TEXT(MID(R31,3,2)+IF(RIGHT(R31,1)="4",1,0),"00")&"Q"&MOD(RIGHT(R31,1),4)+1 | T31: ="FY"&TEXT(MID(S31,3,2)+IF(RIGHT(S31,1)="4",1,0),"00")&"Q"&MOD(RIGHT(S31,1),4)+1 | U31: ="FY"&TEXT(MID(T31,3,2)+IF(RIGHT(T31,1)="4",1,0),"00")&"Q"&MOD(RIGHT(T31,1),4)+1
C35: Multiplier | H35: =$H$10
C36: Pricing
D37: Price Inflation | N37: ='Assumptions&Scenario'!N159 | O37: ='Assumptions&Scenario'!O159 | P37: ='Assumptions&Scenario'!P159 | Q37: ='Assumptions&Scenario'!Q159 | R37: ='Assumptions&Scenario'!R159 | S37: ='Assumptions&Scenario'!S159 | T37: ='Assumptions&Scenario'!T159 | U37: ='Assumptions&Scenario'!U159
D38: Price | H38: =$H$13 | J38: =HistoricalData!R124 | K38: =HistoricalData!S124 | L38: =HistoricalData!T124 | M38: =HistoricalData!U124 | N38: =J38*(1+N37) | O38: =K38*(1+O37) | P38: =L38*(1+P37) | Q38: =M38*(1+Q37) | R38: =N38*(1+R37) | S38: =O38*(1+S37) | T38: =P38*(1+T37) | U38: =Q38*(1+U37)
C39: Volume
D40: Capacity | N40: ='Assumptions&Scenario'!K41 | O40: =N40 | P40: =O40 | Q40: =P40 | R40: =Q40 | S40: =R40 | T40: =S40 | U40: =T40
D41: Volume Growth | N41: ='Assumptions&Scenario'!N165 | O41: ='Assumptions&Scenario'!O165 | P41: ='Assumptions&Scenario'!P165 | Q41: ='Assumptions&Scenario'!Q165 | R41: ='Assumptions&Scenario'!R165 | S41: ='Assumptions&Scenario'!S165 | T41: ='Assumptions&Scenario'!T165 | U41: ='Assumptions&Scenario'!U165
D42: Volume | H42: =$H$17 | J42: =HistoricalData!R121 | K42: =HistoricalData!S121 | L42: =HistoricalData!T121 | M42: =HistoricalData!U121 | N42: =J42*(1+N41) | O42: =K42*(1+O41) | P42: =L42*(1+P41) | Q42: =M42*(1+Q41) | R42: =N42*(1+R41) | S42: =O42*(1+S41) | T42: =P42*(1+T41) | U42: =Q42*(1+U41)
D43: Utilization | N43: =IFERROR(SUM(K42:N42)/N40, 0) | O43: =IFERROR(SUM(L42:O42)/O40, 0) | P43: =IFERROR(SUM(M42:P42)/P40, 0) | Q43: =IFERROR(SUM(N42:Q42)/Q40, 0) | R43: =IFERROR(SUM(O42:R42)/R40, 0) | S43: =IFERROR(SUM(P42:S42)/S40, 0) | T43: =IFERROR(SUM(Q42:T42)/T40, 0) | U43: =IFERROR(SUM(R42:U42)/U40, 0)
C45: Revenue
D46: Revenue | H46: =$H$21 | N46: =N38*N42/$H$35 | O46: =O38*O42/$H$35 | P46: =P38*P42/$H$35 | Q46: =Q38*Q42/$H$35 | R46: =R38*R42/$H$35 | S46: =S38*S42/$H$35 | T46: =T38*T42/$H$35 | U46: =U38*U42/$H$35
D47: Exchange Rate | H47: =$H$22 | N47: ='Assumptions&Scenario'!N171 | O47: ='Assumptions&Scenario'!O171 | P47: ='Assumptions&Scenario'!P171 | Q47: ='Assumptions&Scenario'!Q171 | R47: ='Assumptions&Scenario'!R171 | S47: ='Assumptions&Scenario'!S171 | T47: ='Assumptions&Scenario'!T171 | U47: ='Assumptions&Scenario'!U171
D48: Revenue | H48: =H23 | J48: =HistoricalData!R94 | K48: =HistoricalData!S94 | L48: =HistoricalData!T94 | M48: =HistoricalData!U94 | N48: =N46*N47/$H47 | O48: =O46*O47/$H47 | P48: =P46*P47/$H47 | Q48: =Q46*Q47/$H47 | R48: =R46*R47/$H47 | S48: =S46*S47/$H47 | T48: =T46*T47/$H47 | U48: =U46*U47/$H47
D49: Revenue g% | N49: =IFERROR(N48/J48-1, 0) | O49: =IFERROR(O48/K48-1, 0) | P49: =IFERROR(P48/L48-1, 0) | Q49: =IFERROR(Q48/M48-1, 0) | R49: =IFERROR(R48/N48-1, 0) | S49: =IFERROR(S48/O48-1, 0) | T49: =IFERROR(T48/P48-1, 0) | U49: =IFERROR(U48/Q48-1, 0)
U52: =$U$2
B53: ='Assumptions&Scenario'!$K$10
...

Sheet ModelBFSI
U2: =UPPER("Currently Running " & CHOOSE('Assumptions&Scenario'!H88, 'Assumptions&Scenario'!D102,'Assumptions&Scenario'!D103,'Assumptions&Scenario'!D104) & " Scenario")
B3: ='Assumptions&Scenario'!$K$10
B4: Annual Income Expense History | Y4: Annual Income Expense Forecast
C6: FIN Years | J6: ="FY"&TEXT(RIGHT(K6,2)-(COLUMN(K6)-COLUMN()),"00") | K6: ="FY"&TEXT(RIGHT(L6,2)-(COLUMN(L6)-COLUMN()),"00") | L6: ="FY"&TEXT(RIGHT(M6,2)-(COLUMN(M6)-COLUMN()),"00") | M6: ="FY"&TEXT(RIGHT(N6,2)-(COLUMN(N6)-COLUMN()),"00") | N6: ="FY"&TEXT(RIGHT(O6,2)-(COLUMN(O6)-COLUMN()),"00") | O6: ="FY"&TEXT(RIGHT(P6,2)-(COLUMN(P6)-COLUMN()),"00") | P6: ="FY"&TEXT(RIGHT(Q6,2)-(COLUMN(Q6)-COLUMN()),"00") | Q6: ="FY"&TEXT(RIGHT(R6,2)-(COLUMN(R6)-COLUMN()),"00") | ... T6: ="FY"&TEXT(RIGHT(U6,2)-(COLUMN(U6)-COLUMN()),"00") | U6: ="FY"&TEXT(DATE(YEAR('Data Sheet'!$K$16)+(MONTH('Data Sheet'!$K$16)>3),1,1),"YY") | Y6: =Model!$L$6 | Z6: ="FY"&TEXT(RIGHT(Y6,2)+COLUMN()-COLUMN(Y6),"00") | AA6: ="FY"&TEXT(RIGHT(Z6,2)+COLUMN()-COLUMN(Z6),"00") | AB6: ="FY"&TEXT(RIGHT(AA6,2)+COLUMN()-COLUMN(AA6),"00") | AC6: ="FY"&TEXT(RIGHT(AB6,2)+COLUMN()-COLUMN(AB6),"00") | AD6: ="FY"&TEXT(RIGHT(AC6,2)+COLUMN()-COLUMN(AC6),"00") | AE6: ="FY"&TEXT(RIGHT(AD6,2)+COLUMN()-COLUMN(AD6),"00") | AF6: ="FY"&TEXT(RIGHT(AE6,2)+COLUMN()-COLUMN(AE6),"00") | AG6: ="FY"&TEXT(RIGHT(AF6,2)+COLUMN()-COLUMN(AF6),"00") | AH6: ="FY"&TEXT(RIGHT(AG6,2)+COLUMN()-COLUMN(AG6),"00")
C10: Interest Income | H10: =HistoricalData!H10 | Y10: {=IFERROR(_xlfn.FORECAST.LINEAR(RIGHT(Y$6,2), $J10:$U10, VALUE(RIGHT($J$6:$U$6,2))), 0)} | Z10: {=IFERROR(_xlfn.FORECAST.LINEAR(RIGHT(Z$6,2), $J10:$U10, VALUE(RIGHT($J$6:$U$6,2))), 0)} | AA10: {=IFERROR(_xlfn.FORECAST.LINEAR(RIGHT(AA$6,2), $J10:$U10, VALUE(RIGHT($J$6:$U$6,2))), 0)} | AB10: {=IFERROR(_xlfn.FORECAST.LINEAR(RIGHT(AB$6,2), $J10:$U10, VALUE(RIGHT($J$6:$U$6,2))), 0)} | AC10: {=IFERROR(_xlfn.FORECAST.LINEAR(RIGHT(AC$6,2), $J10:$U10, VALUE(RIGHT($J$6:$U$6,2))), 0)} | AD10: {=IFERROR(_xlfn.FORECAST.LINEAR(RIGHT(AD$6,2), $J10:$U10, VALUE(RIGHT($J$6:$U$6,2))), 0)} | AE10: {=IFERROR(_xlfn.FORECAST.LINEAR(RIGHT(AE$6,2), $J10:$U10, VALUE(RIGHT($J$6:$U$6,2))), 0)} | AF10: {=IFERROR(_xlfn.FORECAST.LINEAR(RIGHT(AF$6,2), $J10:$U10, VALUE(RIGHT($J$6:$U$6,2))), 0)} | ... AH10: {=IFERROR(_xlfn.FORECAST.LINEAR(RIGHT(AH$6,2), $J10:$U10, VALUE(RIGHT($J$6:$U$6,2))), 0)}
C11: Interest Expenses | Y11: {=IFERROR(_xlfn.FORECAST.LINEAR(RIGHT(Y$6,2), $J11:$U11, VALUE(RIGHT($J$6:$U$6,2))), 0)} | Z11: {=IFERROR(_xlfn.FORECAST.LINEAR(RIGHT(Z$6,2), $J11:$U11, VALUE(RIGHT($J$6:$U$6,2))), 0)} | AA11: {=IFERROR(_xlfn.FORECAST.LINEAR(RIGHT(AA$6,2), $J11:$U11, VALUE(RIGHT($J$6:$U$6,2))), 0)} | AB11: {=IFERROR(_xlfn.FORECAST.LINEAR(RIGHT(AB$6,2), $J11:$U11, VALUE(RIGHT($J$6:$U$6,2))), 0)} | AC11: {=IFERROR(_xlfn.FORECAST.LINEAR(RIGHT(AC$6,2), $J11:$U11, VALUE(RIGHT($J$6:$U$6,2))), 0)} | AD11: {=IFERROR(_xlfn.FORECAST.LINEAR(RIGHT(AD$6,2), $J11:$U11, VALUE(RIGHT($J$6:$U$6,2))), 0)} | AE11: {=IFERROR(_xlfn.FORECAST.LINEAR(RIGHT(AE$6,2), $J11:$U11, VALUE(RIGHT($J$6:$U$6,2))), 0)} | AF11: {=IFERROR(_xlfn.FORECAST.LINEAR(RIGHT(AF$6,2), $J11:$U11, VALUE(RIGHT($J$6:$U$6,2))), 0)} | ... AH11: {=IFERROR(_xlfn.FORECAST.LINEAR(RIGHT(AH$6,2), $J11:$U11, VALUE(RIGHT($J$6:$U$6,2))), 0)}
C12: Net Interest Income | Y12: {=IFERROR(_xlfn.FORECAST.LINEAR(RIGHT(Y$6,2), $J12:$U12, VALUE(RIGHT($J$6:$U$6,2))), 0)} | Z12: {=IFERROR(_xlfn.FORECAST.LINEAR(RIGHT(Z$6,2), $J12:$U12, VALUE(RIGHT($J$6:$U$6,2))), 0)} | AA12: {=IFERROR(_xlfn.FORECAST.LINEAR(RIGHT(AA$6,2), $J12:$U12, VALUE(RIGHT($J$6:$U$6,2))), 0)} | AB12: {=IFERROR(_xlfn.FORECAST.LINEAR(RIGHT(AB$6,2), $J12:$U12, VALUE(RIGHT($J$6:$U$6,2))), 0)} | AC12: {=IFERROR(_xlfn.FORECAST.LINEAR(RIGHT(AC$6,2), $J12:$U12, VALUE(RIGHT($J$6:$U$6,2))), 0)} | AD12: {=IFERROR(_xlfn.FORECAST.LINEAR(RIGHT(AD$6,2), $J12:$U12, VALUE(RIGHT($J$6:$U$6,2))), 0)} | AE12: {=IFERROR(_xlfn.FORECAST.LINEAR(RIGHT(AE$6,2), $J12:$U12, VALUE(RIGHT($J$6:$U$6,2))), 0)} | AF12: {=IFERROR(_xlfn.FORECAST.LINEAR(RIGHT(AF$6,2), $J12:$U12, VALUE(RIGHT($J$6:$U$6,2))), 0)} | ... AH12: {=IFERROR(_xlfn.FORECAST.LINEAR(RIGHT(AH$6,2), $J12:$U12, VALUE(RIGHT($J$6:$U$6,2))), 0)}
C15: Net Interest Margin | Y15: {=IFERROR(_xlfn.FORECAST.LINEAR(RIGHT(Y$6,2), $J15:$U15, VALUE(RIGHT($J$6:$U$6,2))), 0)} | Z15: {=IFERROR(_xlfn.FORECAST.LINEAR(RIGHT(Z$6,2), $J15:$U15, VALUE(RIGHT($J$6:$U$6,2))), 0)} | AA15: {=IFERROR(_xlfn.FORECAST.LINEAR(RIGHT(AA$6,2), $J15:$U15, VALUE(RIGHT($J$6:$U$6,2))), 0)} | AB15: {=IFERROR(_xlfn.FORECAST.LINEAR(RIGHT(AB$6,2), $J15:$U15, VALUE(RIGHT($J$6:$U$6,2))), 0)} | AC15: {=IFERROR(_xlfn.FORECAST.LINEAR(RIGHT(AC$6,2), $J15:$U15, VALUE(RIGHT($J$6:$U$6,2))), 0)} | AD15: {=IFERROR(_xlfn.FORECAST.LINEAR(RIGHT(AD$6,2), $J15:$U15, VALUE(RIGHT($J$6:$U$6,2))), 0)} | AE15: {=IFERROR(_xlfn.FORECAST.LINEAR(RIGHT(AE$6,2), $J15:$U15, VALUE(RIGHT($J$6:$U$6,2))), 0)} | AF15: {=IFERROR(_xlfn.FORECAST.LINEAR(RIGHT(AF$6,2), $J15:$U15, VALUE(RIGHT($J$6:$U$6,2))), 0)} | ... AH15: {=IFERROR(_xlfn.FORECAST.LINEAR(RIGHT(AH$6,2), $J15:$U15, VALUE(RIGHT($J$6:$U$6,2))), 0)}
C17: Other Income | Y17: {=IFERROR(_xlfn.FORECAST.LINEAR(RIGHT(Y$6,2), $J17:$U17, VALUE(RIGHT($J$6:$U$6,2))), 0)} | Z17: {=IFERROR(_xlfn.FORECAST.LINEAR(RIGHT(Z$6,2), $J17:$U17, VALUE(RIGHT($J$6:$U$6,2))), 0)} | AA17: {=IFERROR(_xlfn.FORECAST.LINEAR(RIGHT(AA$6,2), $J17:$U17, VALUE(RIGHT($J$6:$U$6,2))), 0)} | AB17: {=IFERROR(_xlfn.FORECAST.LINEAR(RIGHT(AB$6,2), $J17:$U17, VALUE(RIGHT($J$6:$U$6,2))), 0)} | AC17: {=IFERROR(_xlfn.FORECAST.LINEAR(RIGHT(AC$6,2), $J17:$U17, VALUE(RIGHT($J$6:$U$6,2))), 0)} | AD17: {=IFERROR(_xlfn.FORECAST.LINEAR(RIGHT(AD$6,2), $J17:$U17, VALUE(RIGHT($J$6:$U$6,2))), 0)} | AE17: {=IFERROR(_xlfn.FORECAST.LINEAR(RIGHT(AE$6,2), $J17:$U17, VALUE(RIGHT($J$6:$U$6,2))), 0)} | AF17: {=IFERROR(_xlfn.FORECAST.LINEAR(RIGHT(AF$6,2), $J17:$U17, VALUE(RIGHT($J$6:$U$6,2))), 0)} | ... AH17: {=IFERROR(_xlfn.FORECAST.LINEAR(RIGHT(AH$6,2), $J17:$U17, VALUE(RIGHT($J$6:$U$6,2))), 0)}
C18: Total Income | Y18: {=IFERROR(_xlfn.FORECAST.LINEAR(RIGHT(Y$6,2), $J18:$U18, VALUE(RIGHT($J$6:$U$6,2))), 0)} | Z18: {=IFERROR(_xlfn.FORECAST.LINEAR(RIGHT(Z$6,2), $J18:$U18, VALUE(RIGHT($J$6:$U$6,2))), 0)} | AA18: {=IFERROR(_xlfn.FORECAST.LINEAR(RIGHT(AA$6,2), $J18:$U18, VALUE(RIGHT($J$6:$U$6,2))), 0)} | AB18: {=IFERROR(_xlfn.FORECAST.LINEAR(RIGHT(AB$6,2), $J18:$U18, VALUE(RIGHT($J$6:$U$6,2))), 0)} | AC18: {=IFERROR(_xlfn.FORECAST.LINEAR(RIGHT(AC$6,2), $J18:$U18, VALUE(RIGHT($J$6:$U$6,2))), 0)} | AD18: {=IFERROR(_xlfn.FORECAST.LINEAR(RIGHT(AD$6,2), $J18:$U18, VALUE(RIGHT($J$6:$U$6,2))), 0)} | AE18: {=IFERROR(_xlfn.FORECAST.LINEAR(RIGHT(AE$6,2), $J18:$U18, VALUE(RIGHT($J$6:$U$6,2))), 0)} | AF18: {=IFERROR(_xlfn.FORECAST.LINEAR(RIGHT(AF$6,2), $J18:$U18, VALUE(RIGHT($J$6:$U$6,2))), 0)} | ... AH18: {=IFERROR(_xlfn.FORECAST.LINEAR(RIGHT(AH$6,2), $J18:$U18, VALUE(RIGHT($J$6:$U$6,2))), 0)}
C20: Pre Provision Profit | Y20: {=IFERROR(_xlfn.FORECAST.LINEAR(RIGHT(Y$6,2), $J20:$U20, VALUE(RIGHT($J$6:$U$6,2))), 0)} | Z20: {=IFERROR(_xlfn.FORECAST.LINEAR(RIGHT(Z$6,2), $J20:$U20, VALUE(RIGHT($J$6:$U$6,2))), 0)} | AA20: {=IFERROR(_xlfn.FORECAST.LINEAR(RIGHT(AA$6,2), $J20:$U20, VALUE(RIGHT($J$6:$U$6,2))), 0)} | AB20: {=IFERROR(_xlfn.FORECAST.LINEAR(RIGHT(AB$6,2), $J20:$U20, VALUE(RIGHT($J$6:$U$6,2))), 0)} | AC20: {=IFERROR(_xlfn.FORECAST.LINEAR(RIGHT(AC$6,2), $J20:$U20, VALUE(RIGHT($J$6:$U$6,2))), 0)} | AD20: {=IFERROR(_xlfn.FORECAST.LINEAR(RIGHT(AD$6,2), $J20:$U20, VALUE(RIGHT($J$6:$U$6,2))), 0)} | AE20: {=IFERROR(_xlfn.FORECAST.LINEAR(RIGHT(AE$6,2), $J20:$U20, VALUE(RIGHT($J$6:$U$6,2))), 0)} | AF20: {=IFERROR(_xlfn.FORECAST.LINEAR(RIGHT(AF$6,2), $J20:$U20, VALUE(RIGHT($J$6:$U$6,2))), 0)} | ... AH20: {=IFERROR(_xlfn.FORECAST.LINEAR(RIGHT(AH$6,2), $J20:$U20, VALUE(RIGHT($J$6:$U$6,2))), 0)}
C22: Provision | Y22: {=IFERROR(_xlfn.FORECAST.LINEAR(RIGHT(Y$6,2), $J22:$U22, VALUE(RIGHT($J$6:$U$6,2))), 0)} | Z22: {=IFERROR(_xlfn.FORECAST.LINEAR(RIGHT(Z$6,2), $J22:$U22, VALUE(RIGHT($J$6:$U$6,2))), 0)} | AA22: {=IFERROR(_xlfn.FORECAST.LINEAR(RIGHT(AA$6,2), $J22:$U22, VALUE(RIGHT($J$6:$U$6,2))), 0)} | AB22: {=IFERROR(_xlfn.FORECAST.LINEAR(RIGHT(AB$6,2), $J22:$U22, VALUE(RIGHT($J$6:$U$6,2))), 0)} | AC22: {=IFERROR(_xlfn.FORECAST.LINEAR(RIGHT(AC$6,2), $J22:$U22, VALUE(RIGHT($J$6:$U$6,2))), 0)} | AD22: {=IFERROR(_xlfn.FORECAST.LINEAR(RIGHT(AD$6,2), $J22:$U22, VALUE(RIGHT($J$6:$U$6,2))), 0)} | AE22: {=IFERROR(_xlfn.FORECAST.LINEAR(RIGHT(AE$6,2), $J22:$U22, VALUE(RIGHT($J$6:$U$6,2))), 0)} | AF22: {=IFERROR(_xlfn.FORECAST.LINEAR(RIGHT(AF$6,2), $J22:$U22, VALUE(RIGHT($J$6:$U$6,2))), 0)} | ... AH22: {=IFERROR(_xlfn.FORECAST.LINEAR(RIGHT(AH$6,2), $J22:$U22, VALUE(RIGHT($J$6:$U$6,2))), 0)}
C24: Profit before Tax
C26: Tax
C27: Standalone Profit | Y27: {=IFERROR(_xlfn.FORECAST.LINEAR(RIGHT(Y$6,2), $J27:$U27, VALUE(RIGHT($J$6:$U$6,2))), 0)} | Z27: {=IFERROR(_xlfn.FORECAST.LINEAR(RIGHT(Z$6,2), $J27:$U27, VALUE(RIGHT($J$6:$U$6,2))), 0)} | AA27: {=IFERROR(_xlfn.FORECAST.LINEAR(RIGHT(AA$6,2), $J27:$U27, VALUE(RIGHT($J$6:$U$6,2))), 0)} | AB27: {=IFERROR(_xlfn.FORECAST.LINEAR(RIGHT(AB$6,2), $J27:$U27, VALUE(RIGHT($J$6:$U$6,2))), 0)} | AC27: {=IFERROR(_xlfn.FORECAST.LINEAR(RIGHT(AC$6,2), $J27:$U27, VALUE(RIGHT($J$6:$U$6,2))), 0)} | AD27: {=IFERROR(_xlfn.FORECAST.LINEAR(RIGHT(AD$6,2), $J27:$U27, VALUE(RIGHT($J$6:$U$6,2))), 0)} | AE27: {=IFERROR(_xlfn.FORECAST.LINEAR(RIGHT(AE$6,2), $J27:$U27, VALUE(RIGHT($J$6:$U$6,2))), 0)} | AF27: {=IFERROR(_xlfn.FORECAST.LINEAR(RIGHT(AF$6,2), $J27:$U27, VALUE(RIGHT($J$6:$U$6,2))), 0)} | ... AH27: {=IFERROR(_xlfn.FORECAST.LINEAR(RIGHT(AH$6,2), $J27:$U27, VALUE(RIGHT($J$6:$U$6,2))), 0)}
C29: Subsidiary Profit
D30: Subsidiary 1 | Y30: {=IFERROR(_xlfn.FORECAST.LINEAR(RIGHT(Y$6,2), $J30:$U30, VALUE(RIGHT($J$6:$U$6,2))), 0)} | Z30: {=IFERROR(_xlfn.FORECAST.LINEAR(RIGHT(Z$6,2), $J30:$U30, VALUE(RIGHT($J$6:$U$6,2))), 0)} | AA30: {=IFERROR(_xlfn.FORECAST.LINEAR(RIGHT(AA$6,2), $J30:$U30, VALUE(RIGHT($J$6:$U$6,2))), 0)} | AB30: {=IFERROR(_xlfn.FORECAST.LINEAR(RIGHT(AB$6,2), $J30:$U30, VALUE(RIGHT($J$6:$U$6,2))), 0)} | AC30: {=IFERROR(_xlfn.FORECAST.LINEAR(RIGHT(AC$6,2), $J30:$U30, VALUE(RIGHT($J$6:$U$6,2))), 0)} | AD30: {=IFERROR(_xlfn.FORECAST.LINEAR(RIGHT(AD$6,2), $J30:$U30, VALUE(RIGHT($J$6:$U$6,2))), 0)} | AE30: {=IFERROR(_xlfn.FORECAST.LINEAR(RIGHT(AE$6,2), $J30:$U30, VALUE(RIGHT($J$6:$U$6,2))), 0)} | AF30: {=IFERROR(_xlfn.FORECAST.LINEAR(RIGHT(AF$6,2), $J30:$U30, VALUE(RIGHT($J$6:$U$6,2))), 0)} | ... AH30: {=IFERROR(_xlfn.FORECAST.LINEAR(RIGHT(AH$6,2), $J30:$U30, VALUE(RIGHT($J$6:$U$6,2))), 0)}
D31: Subsidiary 2 | Y31: {=IFERROR(_xlfn.FORECAST.LINEAR(RIGHT(Y$6,2), $J31:$U31, VALUE(RIGHT($J$6:$U$6,2))), 0)} | Z31: {=IFERROR(_xlfn.FORECAST.LINEAR(RIGHT(Z$6,2), $J31:$U31, VALUE(RIGHT($J$6:$U$6,2))), 0)} | AA31: {=IFERROR(_xlfn.FORECAST.LINEAR(RIGHT(AA$6,2), $J31:$U31, VALUE(RIGHT($J$6:$U$6,2))), 0)} | AB31: {=IFERROR(_xlfn.FORECAST.LINEAR(RIGHT(AB$6,2), $J31:$U31, VALUE(RIGHT($J$6:$U$6,2))), 0)} | AC31: {=IFERROR(_xlfn.FORECAST.LINEAR(RIGHT(AC$6,2), $J31:$U31, VALUE(RIGHT($J$6:$U$6,2))), 0)} | AD31: {=IFERROR(_xlfn.FORECAST.LINEAR(RIGHT(AD$6,2), $J31:$U31, VALUE(RIGHT($J$6:$U$6,2))), 0)} | AE31: {=IFERROR(_xlfn.FORECAST.LINEAR(RIGHT(AE$6,2), $J31:$U31, VALUE(RIGHT($J$6:$U$6,2))), 0)} | AF31: {=IFERROR(_xlfn.FORECAST.LINEAR(RIGHT(AF$6,2), $J31:$U31, VALUE(RIGHT($J$6:$U$6,2))), 0)} | ... AH31: {=IFERROR(_xlfn.FORECAST.LINEAR(RIGHT(AH$6,2), $J31:$U31, VALUE(RIGHT($J$6:$U$6,2))), 0)}
D32: Subsidiary 3 | Y32: {=IFERROR(_xlfn.FORECAST.LINEAR(RIGHT(Y$6,2), $J32:$U32, VALUE(RIGHT($J$6:$U$6,2))), 0)} | Z32: {=IFERROR(_xlfn.FORECAST.LINEAR(RIGHT(Z$6,2), $J32:$U32, VALUE(RIGHT($J$6:$U$6,2))), 0)} | AA32: {=IFERROR(_xlfn.FORECAST.LINEAR(RIGHT(AA$6,2), $J32:$U32, VALUE(RIGHT($J$6:$U$6,2))), 0)} | AB32: {=IFERROR(_xlfn.FORECAST.LINEAR(RIGHT(AB$6,2), $J32:$U32, VALUE(RIGHT($J$6:$U$6,2))), 0)} | AC32: {=IFERROR(_xlfn.FORECAST.LINEAR(RIGHT(AC$6,2), $J32:$U32, VALUE(RIGHT($J$6:$U$6,2))), 0)} | AD32: {=IFERROR(_xlfn.FORECAST.LINEAR(RIGHT(AD$6,2), $J32:$U32, VALUE(RIGHT($J$6:$U$6,2))), 0)} | AE32: {=IFERROR(_xlfn.FORECAST.LINEAR(RIGHT(AE$6,2), $J32:$U32, VALUE(RIGHT($J$6:$U$6,2))), 0)} | AF32: {=IFERROR(_xlfn.FORECAST.LINEAR(RIGHT(AF$6,2), $J32:$U32, VALUE(RIGHT($J$6:$U$6,2))), 0)} | ... AH32: {=IFERROR(_xlfn.FORECAST.LINEAR(RIGHT(AH$6,2), $J32:$U32, VALUE(RIGHT($J$6:$U$6,2))), 0)}
D33: Subsidiary 4 | Y33: {=IFERROR(_xlfn.FORECAST.LINEAR(RIGHT(Y$6,2), $J33:$U33, VALUE(RIGHT($J$6:$U$6,2))), 0)} | Z33: {=IFERROR(_xlfn.FORECAST.LINEAR(RIGHT(Z$6,2), $J33:$U33, VALUE(RIGHT($J$6:$U$6,2))), 0)} | AA33: {=IFERROR(_xlfn.FORECAST.LINEAR(RIGHT(AA$6,2), $J33:$U33, VALUE(RIGHT($J$6:$U$6,2))), 0)} | AB33: {=IFERROR(_xlfn.FORECAST.LINEAR(RIGHT(AB$6,2), $J33:$U33, VALUE(RIGHT($J$6:$U$6,2))), 0)} | AC33: {=IFERROR(_xlfn.FORECAST.LINEAR(RIGHT(AC$6,2), $J33:$U33, VALUE(RIGHT($J$6:$U$6,2))), 0)} | AD33: {=IFERROR(_xlfn.FORECAST.LINEAR(RIGHT(AD$6,2), $J33:$U33, VALUE(RIGHT($J$6:$U$6,2))), 0)} | AE33: {=IFERROR(_xlfn.FORECAST.LINEAR(RIGHT(AE$6,2), $J33:$U33, VALUE(RIGHT($J$6:$U$6,2))), 0)} | AF33: {=IFERROR(_xlfn.FORECAST.LINEAR(RIGHT(AF$6,2), $J33:$U33, VALUE(RIGHT($J$6:$U$6,2))), 0)} | ... AH33: {=IFERROR(_xlfn.FORECAST.LINEAR(RIGHT(AH$6,2), $J33:$U33, VALUE(RIGHT($J$6:$U$6,2))), 0)}
D34: Subsidiary 5 | Y34: {=IFERROR(_xlfn.FORECAST.LINEAR(RIGHT(Y$6,2), $J34:$U34, VALUE(RIGHT($J$6:$U$6,2))), 0)} | Z34: {=IFERROR(_xlfn.FORECAST.LINEAR(RIGHT(Z$6,2), $J34:$U34, VALUE(RIGHT($J$6:$U$6,2))), 0)} | AA34: {=IFERROR(_xlfn.FORECAST.LINEAR(RIGHT(AA$6,2), $J34:$U34, VALUE(RIGHT($J$6:$U$6,2))), 0)} | AB34: {=IFERROR(_xlfn.FORECAST.LINEAR(RIGHT(AB$6,2), $J34:$U34, VALUE(RIGHT($J$6:$U$6,2))), 0)} | AC34: {=IFERROR(_xlfn.FORECAST.LINEAR(RIGHT(AC$6,2), $J34:$U34, VALUE(RIGHT($J$6:$U$6,2))), 0)} | AD34: {=IFERROR(_xlfn.FORECAST.LINEAR(RIGHT(AD$6,2), $J34:$U34, VALUE(RIGHT($J$6:$U$6,2))), 0)} | AE34: {=IFERROR(_xlfn.FORECAST.LINEAR(RIGHT(AE$6,2), $J34:$U34, VALUE(RIGHT($J$6:$U$6,2))), 0)} | AF34: {=IFERROR(_xlfn.FORECAST.LINEAR(RIGHT(AF$6,2), $J34:$U34, VALUE(RIGHT($J$6:$U$6,2))), 0)} | ... AH34: {=IFERROR(_xlfn.FORECAST.LINEAR(RIGHT(AH$6,2), $J34:$U34, VALUE(RIGHT($J$6:$U$6,2))), 0)}
D35: Subsidiary 6 | Y35: {=IFERROR(_xlfn.FORECAST.LINEAR(RIGHT(Y$6,2), $J35:$U35, VALUE(RIGHT($J$6:$U$6,2))), 0)} | Z35: {=IFERROR(_xlfn.FORECAST.LINEAR(RIGHT(Z$6,2), $J35:$U35, VALUE(RIGHT($J$6:$U$6,2))), 0)} | AA35: {=IFERROR(_xlfn.FORECAST.LINEAR(RIGHT(AA$6,2), $J35:$U35, VALUE(RIGHT($J$6:$U$6,2))), 0)} | AB35: {=IFERROR(_xlfn.FORECAST.LINEAR(RIGHT(AB$6,2), $J35:$U35, VALUE(RIGHT($J$6:$U$6,2))), 0)} | AC35: {=IFERROR(_xlfn.FORECAST.LINEAR(RIGHT(AC$6,2), $J35:$U35, VALUE(RIGHT($J$6:$U$6,2))), 0)} | AD35: {=IFERROR(_xlfn.FORECAST.LINEAR(RIGHT(AD$6,2), $J35:$U35, VALUE(RIGHT($J$6:$U$6,2))), 0)} | AE35: {=IFERROR(_xlfn.FORECAST.LINEAR(RIGHT(AE$6,2), $J35:$U35, VALUE(RIGHT($J$6:$U$6,2))), 0)} | AF35: {=IFERROR(_xlfn.FORECAST.LINEAR(RIGHT(AF$6,2), $J35:$U35, VALUE(RIGHT($J$6:$U$6,2))), 0)} | ... AH35: {=IFERROR(_xlfn.FORECAST.LINEAR(RIGHT(AH$6,2), $J35:$U35, VALUE(RIGHT($J$6:$U$6,2))), 0)}
C37: Consolidated Profit | L37: ='Data Sheet'!B30 | M37: ='Data Sheet'!C30 | N37: ='Data Sheet'!D30 | O37: ='Data Sheet'!E30 | P37: ='Data Sheet'!F30 | Q37: ='Data Sheet'!G30 | R37: ='Data Sheet'!H30 | S37: ='Data Sheet'!I30 | ... U37: ='Data Sheet'!K30 | Y37: {=IFERROR(_xlfn.FORECAST.LINEAR(RIGHT(Y$6,2), $J37:$U37, VALUE(RIGHT($J$6:$U$6,2))), 0)} | Z37: {=IFERROR(_xlfn.FORECAST.LINEAR(RIGHT(Z$6,2), $J37:$U37, VALUE(RIGHT($J$6:$U$6,2))), 0)} | AA37: {=IFERROR(_xlfn.FORECAST.LINEAR(RIGHT(AA$6,2), $J37:$U37, VALUE(RIGHT($J$6:$U$6,2))), 0)} | AB37: {=IFERROR(_xlfn.FORECAST.LINEAR(RIGHT(AB$6,2), $J37:$U37, VALUE(RIGHT($J$6:$U$6,2))), 0)} | AC37: {=IFERROR(_xlfn.FORECAST.LINEAR(RIGHT(AC$6,2), $J37:$U37, VALUE(RIGHT($J$6:$U$6,2))), 0)} | AD37: {=IFERROR(_xlfn.FORECAST.LINEAR(RIGHT(AD$6,2), $J37:$U37, VALUE(RIGHT($J$6:$U$6,2))), 0)} | AE37: {=IFERROR(_xlfn.FORECAST.LINEAR(RIGHT(AE$6,2), $J37:$U37, VALUE(RIGHT($J$6:$U$6,2))), 0)} | AF37: {=IFERROR(_xlfn.FORECAST.LINEAR(RIGHT(AF$6,2), $J37:$U37, VALUE(RIGHT($J$6:$U$6,2))), 0)} | ... AH37: {=IFERROR(_xlfn.FORECAST.LINEAR(RIGHT(AH$6,2), $J37:$U37, VALUE(RIGHT($J$6:$U$6,2))), 0)}
